package ebm.com.mce.gen.feature;

import java.util.Random;

import cpw.mods.fml.common.IWorldGenerator;
import net.minecraft.block.Block;
import net.minecraft.init.Blocks;
import net.minecraft.world.World;
import net.minecraft.world.chunk.IChunkProvider;
import net.minecraft.world.gen.feature.WorldGenerator;

public class WorldGenBasicRoom extends WorldGenerator implements IWorldGenerator {
	public static Block block;

	public WorldGenBasicRoom() {
	}

	@Override
	public void generate(Random random, int chunkX, int chunkZ, World world, IChunkProvider chunkGenerator,
			IChunkProvider chunkProvider) {
	}

	public void setBlock(World world, int x, int y, int z, Block block, int metadata) {
		// Block b1 = world.getBlock(x, y, z);
		world.setBlock(x, y, z, block, metadata, 2);
	}

	public boolean generate(World world, Random rand, int i, int j, int k) {
		this.setBlock(world, i + 0, j + 0, k + 0, block, 0);
		this.setBlock(world, i + 0, j + 0, k + 1, block, 0);
		this.setBlock(world, i + 0, j + 0, k + 2, block, 0);
		this.setBlock(world, i + 0, j + 0, k + 3, block, 0);
		this.setBlock(world, i + 0, j + 0, k + 4, block, 0);
		this.setBlock(world, i + 0, j + 0, k + 5, block, 0);
		this.setBlock(world, i + 0, j + 0, k + 6, block, 0);
		this.setBlock(world, i + 0, j + 0, k + 7, block, 0);
		this.setBlock(world, i + 0, j + 0, k + 8, block, 0);
		this.setBlock(world, i + 0, j + 0, k + 9, block, 0);
		this.setBlock(world, i + 0, j + 0, k + 10, block, 0);
		this.setBlock(world, i + 0, j + 0, k + 11, block, 0);
		this.setBlock(world, i + 0, j + 0, k + 12, block, 0);
		this.setBlock(world, i + 0, j + 1, k + 0, block, 0);
		this.setBlock(world, i + 0, j + 1, k + 1, block, 0);
		this.setBlock(world, i + 0, j + 1, k + 2, block, 0);
		this.setBlock(world, i + 0, j + 1, k + 3, block, 0);
		this.setBlock(world, i + 0, j + 1, k + 4, block, 0);
		this.setBlock(world, i + 0, j + 1, k + 5, block, 0);
		this.setBlock(world, i + 0, j + 1, k + 6, block, 0);
		this.setBlock(world, i + 0, j + 1, k + 7, block, 0);
		this.setBlock(world, i + 0, j + 1, k + 8, block, 0);
		this.setBlock(world, i + 0, j + 1, k + 9, block, 0);
		this.setBlock(world, i + 0, j + 1, k + 10, block, 0);
		this.setBlock(world, i + 0, j + 1, k + 11, block, 0);
		this.setBlock(world, i + 0, j + 1, k + 12, block, 0);
		this.setBlock(world, i + 0, j + 2, k + 0, block, 0);
		this.setBlock(world, i + 0, j + 2, k + 1, block, 0);
		this.setBlock(world, i + 0, j + 2, k + 2, block, 0);
		this.setBlock(world, i + 0, j + 2, k + 3, block, 0);
		this.setBlock(world, i + 0, j + 2, k + 4, block, 0);
		this.setBlock(world, i + 0, j + 2, k + 5, block, 0);
		this.setBlock(world, i + 0, j + 2, k + 6, block, 0);
		this.setBlock(world, i + 0, j + 2, k + 7, block, 0);
		this.setBlock(world, i + 0, j + 2, k + 8, block, 0);
		this.setBlock(world, i + 0, j + 2, k + 9, block, 0);
		this.setBlock(world, i + 0, j + 2, k + 10, block, 0);
		this.setBlock(world, i + 0, j + 2, k + 11, block, 0);
		this.setBlock(world, i + 0, j + 2, k + 12, block, 0);
		this.setBlock(world, i + 0, j + 3, k + 0, block, 0);
		this.setBlock(world, i + 0, j + 3, k + 1, block, 0);
		this.setBlock(world, i + 0, j + 3, k + 2, block, 0);
		this.setBlock(world, i + 0, j + 3, k + 3, block, 0);
		this.setBlock(world, i + 0, j + 3, k + 4, block, 0);
		this.setBlock(world, i + 0, j + 3, k + 5, block, 0);
		this.setBlock(world, i + 0, j + 3, k + 6, block, 0);
		this.setBlock(world, i + 0, j + 3, k + 7, block, 0);
		this.setBlock(world, i + 0, j + 3, k + 8, block, 0);
		this.setBlock(world, i + 0, j + 3, k + 9, block, 0);
		this.setBlock(world, i + 0, j + 3, k + 10, block, 0);
		this.setBlock(world, i + 0, j + 3, k + 11, block, 0);
		this.setBlock(world, i + 0, j + 3, k + 12, block, 0);
		this.setBlock(world, i + 0, j + 4, k + 0, block, 0);
		this.setBlock(world, i + 0, j + 4, k + 1, block, 0);
		this.setBlock(world, i + 0, j + 4, k + 2, block, 0);
		this.setBlock(world, i + 0, j + 4, k + 3, block, 0);
		this.setBlock(world, i + 0, j + 4, k + 4, block, 0);
		this.setBlock(world, i + 0, j + 4, k + 5, block, 0);
		this.setBlock(world, i + 0, j + 4, k + 6, block, 0);
		this.setBlock(world, i + 0, j + 4, k + 7, block, 0);
		this.setBlock(world, i + 0, j + 4, k + 8, block, 0);
		this.setBlock(world, i + 0, j + 4, k + 9, block, 0);
		this.setBlock(world, i + 0, j + 4, k + 10, block, 0);
		this.setBlock(world, i + 0, j + 4, k + 11, block, 0);
		this.setBlock(world, i + 0, j + 4, k + 12, block, 0);
		this.setBlock(world, i + 1, j + 0, k + 0, block, 0);
		this.setBlock(world, i + 1, j + 0, k + 1, block, 0);
		this.setBlock(world, i + 1, j + 0, k + 2, block, 0);
		this.setBlock(world, i + 1, j + 0, k + 3, block, 0);
		this.setBlock(world, i + 1, j + 0, k + 4, block, 0);
		this.setBlock(world, i + 1, j + 0, k + 5, block, 0);
		this.setBlock(world, i + 1, j + 0, k + 6, block, 0);
		this.setBlock(world, i + 1, j + 0, k + 7, block, 0);
		this.setBlock(world, i + 1, j + 0, k + 8, block, 0);
		this.setBlock(world, i + 1, j + 0, k + 9, block, 0);
		this.setBlock(world, i + 1, j + 0, k + 10, block, 0);
		this.setBlock(world, i + 1, j + 0, k + 11, block, 0);
		this.setBlock(world, i + 1, j + 0, k + 12, block, 0);
		this.setBlock(world, i + 1, j + 1, k + 0, block, 0);
		this.setBlock(world, i + 1, j + 1, k + 1, Blocks.air, 0);
		this.setBlock(world, i + 1, j + 1, k + 2, Blocks.air, 0);
		this.setBlock(world, i + 1, j + 1, k + 3, Blocks.air, 0);
		this.setBlock(world, i + 1, j + 1, k + 4, Blocks.air, 0);
		this.setBlock(world, i + 1, j + 1, k + 5, block, 0);
		this.setBlock(world, i + 1, j + 1, k + 6, Blocks.air, 0);
		this.setBlock(world, i + 1, j + 1, k + 7, Blocks.air, 0);
		this.setBlock(world, i + 1, j + 1, k + 8, Blocks.air, 0);
		this.setBlock(world, i + 1, j + 1, k + 9, Blocks.air, 0);
		this.setBlock(world, i + 1, j + 1, k + 10, Blocks.air, 0);
		this.setBlock(world, i + 1, j + 1, k + 11, Blocks.air, 0);
		this.setBlock(world, i + 1, j + 1, k + 12, block, 0);
		this.setBlock(world, i + 1, j + 2, k + 0, block, 0);
		this.setBlock(world, i + 1, j + 2, k + 1, Blocks.air, 0);
		this.setBlock(world, i + 1, j + 2, k + 2, Blocks.air, 0);
		this.setBlock(world, i + 1, j + 2, k + 3, Blocks.air, 0);
		this.setBlock(world, i + 1, j + 2, k + 4, Blocks.air, 0);
		this.setBlock(world, i + 1, j + 2, k + 5, block, 0);
		this.setBlock(world, i + 1, j + 2, k + 6, Blocks.air, 0);
		this.setBlock(world, i + 1, j + 2, k + 7, Blocks.air, 0);
		this.setBlock(world, i + 1, j + 2, k + 8, Blocks.air, 0);
		this.setBlock(world, i + 1, j + 2, k + 9, Blocks.air, 0);
		this.setBlock(world, i + 1, j + 2, k + 10, Blocks.air, 0);
		this.setBlock(world, i + 1, j + 2, k + 11, Blocks.air, 0);
		this.setBlock(world, i + 1, j + 2, k + 12, block, 0);
		this.setBlock(world, i + 1, j + 3, k + 0, block, 0);
		this.setBlock(world, i + 1, j + 3, k + 1, Blocks.air, 0);
		this.setBlock(world, i + 1, j + 3, k + 2, Blocks.air, 0);
		this.setBlock(world, i + 1, j + 3, k + 3, Blocks.air, 0);
		this.setBlock(world, i + 1, j + 3, k + 4, Blocks.air, 0);
		this.setBlock(world, i + 1, j + 3, k + 5, block, 0);
		this.setBlock(world, i + 1, j + 3, k + 6, Blocks.air, 0);
		this.setBlock(world, i + 1, j + 3, k + 7, Blocks.air, 0);
		this.setBlock(world, i + 1, j + 3, k + 8, Blocks.air, 0);
		this.setBlock(world, i + 1, j + 3, k + 9, Blocks.air, 0);
		this.setBlock(world, i + 1, j + 3, k + 10, Blocks.air, 0);
		this.setBlock(world, i + 1, j + 3, k + 11, Blocks.air, 0);
		this.setBlock(world, i + 1, j + 3, k + 12, block, 0);
		this.setBlock(world, i + 1, j + 4, k + 0, block, 0);
		this.setBlock(world, i + 1, j + 4, k + 1, block, 0);
		this.setBlock(world, i + 1, j + 4, k + 2, block, 0);
		this.setBlock(world, i + 1, j + 4, k + 3, block, 0);
		this.setBlock(world, i + 1, j + 4, k + 4, block, 0);
		this.setBlock(world, i + 1, j + 4, k + 5, block, 0);
		this.setBlock(world, i + 1, j + 4, k + 6, block, 0);
		this.setBlock(world, i + 1, j + 4, k + 7, block, 0);
		this.setBlock(world, i + 1, j + 4, k + 8, block, 0);
		this.setBlock(world, i + 1, j + 4, k + 9, block, 0);
		this.setBlock(world, i + 1, j + 4, k + 10, block, 0);
		this.setBlock(world, i + 1, j + 4, k + 11, block, 0);
		this.setBlock(world, i + 1, j + 4, k + 12, block, 0);
		this.setBlock(world, i + 2, j + 0, k + 0, block, 0);
		this.setBlock(world, i + 2, j + 0, k + 1, block, 0);
		this.setBlock(world, i + 2, j + 0, k + 2, block, 0);
		this.setBlock(world, i + 2, j + 0, k + 3, block, 0);
		this.setBlock(world, i + 2, j + 0, k + 4, block, 0);
		this.setBlock(world, i + 2, j + 0, k + 5, block, 0);
		this.setBlock(world, i + 2, j + 0, k + 6, block, 0);
		this.setBlock(world, i + 2, j + 0, k + 7, block, 0);
		this.setBlock(world, i + 2, j + 0, k + 8, block, 0);
		this.setBlock(world, i + 2, j + 0, k + 9, block, 0);
		this.setBlock(world, i + 2, j + 0, k + 10, block, 0);
		this.setBlock(world, i + 2, j + 0, k + 11, block, 0);
		this.setBlock(world, i + 2, j + 0, k + 12, block, 0);
		this.setBlock(world, i + 2, j + 1, k + 0, Blocks.air, 0);
		this.setBlock(world, i + 2, j + 1, k + 1, Blocks.air, 0);
		this.setBlock(world, i + 2, j + 1, k + 2, Blocks.air, 0);
		this.setBlock(world, i + 2, j + 1, k + 3, Blocks.air, 0);
		this.setBlock(world, i + 2, j + 1, k + 4, Blocks.air, 0);
		this.setBlock(world, i + 2, j + 1, k + 5, block, 0);
		this.setBlock(world, i + 2, j + 1, k + 6, Blocks.air, 0);
		this.setBlock(world, i + 2, j + 1, k + 7, Blocks.air, 0);
		this.setBlock(world, i + 2, j + 1, k + 8, Blocks.air, 0);
		this.setBlock(world, i + 2, j + 1, k + 9, Blocks.air, 0);
		this.setBlock(world, i + 2, j + 1, k + 10, Blocks.air, 0);
		this.setBlock(world, i + 2, j + 1, k + 11, Blocks.air, 0);
		this.setBlock(world, i + 2, j + 1, k + 12, block, 0);
		this.setBlock(world, i + 2, j + 2, k + 0, Blocks.air, 0);
		this.setBlock(world, i + 2, j + 2, k + 1, Blocks.air, 0);
		this.setBlock(world, i + 2, j + 2, k + 2, Blocks.air, 0);
		this.setBlock(world, i + 2, j + 2, k + 3, Blocks.air, 0);
		this.setBlock(world, i + 2, j + 2, k + 4, Blocks.air, 0);
		this.setBlock(world, i + 2, j + 2, k + 5, block, 0);
		this.setBlock(world, i + 2, j + 2, k + 6, Blocks.air, 0);
		this.setBlock(world, i + 2, j + 2, k + 7, Blocks.air, 0);
		this.setBlock(world, i + 2, j + 2, k + 8, Blocks.air, 0);
		this.setBlock(world, i + 2, j + 2, k + 9, Blocks.air, 0);
		this.setBlock(world, i + 2, j + 2, k + 10, Blocks.air, 0);
		this.setBlock(world, i + 2, j + 2, k + 11, Blocks.air, 0);
		this.setBlock(world, i + 2, j + 2, k + 12, block, 0);
		this.setBlock(world, i + 2, j + 3, k + 0, block, 0);
		this.setBlock(world, i + 2, j + 3, k + 1, Blocks.air, 0);
		this.setBlock(world, i + 2, j + 3, k + 2, Blocks.air, 0);
		this.setBlock(world, i + 2, j + 3, k + 3, Blocks.air, 0);
		this.setBlock(world, i + 2, j + 3, k + 4, Blocks.air, 0);
		this.setBlock(world, i + 2, j + 3, k + 5, block, 0);
		this.setBlock(world, i + 2, j + 3, k + 6, Blocks.air, 0);
		this.setBlock(world, i + 2, j + 3, k + 7, Blocks.air, 0);
		this.setBlock(world, i + 2, j + 3, k + 8, Blocks.air, 0);
		this.setBlock(world, i + 2, j + 3, k + 9, Blocks.air, 0);
		this.setBlock(world, i + 2, j + 3, k + 10, Blocks.air, 0);
		this.setBlock(world, i + 2, j + 3, k + 11, Blocks.air, 0);
		this.setBlock(world, i + 2, j + 3, k + 12, block, 0);
		this.setBlock(world, i + 2, j + 4, k + 0, block, 0);
		this.setBlock(world, i + 2, j + 4, k + 1, block, 0);
		this.setBlock(world, i + 2, j + 4, k + 2, block, 0);
		this.setBlock(world, i + 2, j + 4, k + 3, block, 0);
		this.setBlock(world, i + 2, j + 4, k + 4, block, 0);
		this.setBlock(world, i + 2, j + 4, k + 5, block, 0);
		this.setBlock(world, i + 2, j + 4, k + 6, block, 0);
		this.setBlock(world, i + 2, j + 4, k + 7, block, 0);
		this.setBlock(world, i + 2, j + 4, k + 8, block, 0);
		this.setBlock(world, i + 2, j + 4, k + 9, block, 0);
		this.setBlock(world, i + 2, j + 4, k + 10, block, 0);
		this.setBlock(world, i + 2, j + 4, k + 11, block, 0);
		this.setBlock(world, i + 2, j + 4, k + 12, block, 0);
		this.setBlock(world, i + 3, j + 0, k + 0, block, 0);
		this.setBlock(world, i + 3, j + 0, k + 1, block, 0);
		this.setBlock(world, i + 3, j + 0, k + 2, block, 0);
		this.setBlock(world, i + 3, j + 0, k + 3, block, 0);
		this.setBlock(world, i + 3, j + 0, k + 4, block, 0);
		this.setBlock(world, i + 3, j + 0, k + 5, block, 0);
		this.setBlock(world, i + 3, j + 0, k + 6, block, 0);
		this.setBlock(world, i + 3, j + 0, k + 7, block, 0);
		this.setBlock(world, i + 3, j + 0, k + 8, block, 0);
		this.setBlock(world, i + 3, j + 0, k + 9, block, 0);
		this.setBlock(world, i + 3, j + 0, k + 10, block, 0);
		this.setBlock(world, i + 3, j + 0, k + 11, block, 0);
		this.setBlock(world, i + 3, j + 0, k + 12, block, 0);
		this.setBlock(world, i + 3, j + 1, k + 0, block, 0);
		this.setBlock(world, i + 3, j + 1, k + 1, Blocks.air, 0);
		this.setBlock(world, i + 3, j + 1, k + 2, Blocks.air, 0);
		this.setBlock(world, i + 3, j + 1, k + 3, Blocks.air, 0);
		this.setBlock(world, i + 3, j + 1, k + 4, Blocks.air, 0);
		this.setBlock(world, i + 3, j + 1, k + 5, block, 0);
		this.setBlock(world, i + 3, j + 1, k + 6, block, 0);
		this.setBlock(world, i + 3, j + 1, k + 7, block, 0);
		this.setBlock(world, i + 3, j + 1, k + 8, block, 0);
		this.setBlock(world, i + 3, j + 1, k + 9, Blocks.air, 0);
		this.setBlock(world, i + 3, j + 1, k + 10, block, 0);
		this.setBlock(world, i + 3, j + 1, k + 11, block, 0);
		this.setBlock(world, i + 3, j + 1, k + 12, block, 0);
		this.setBlock(world, i + 3, j + 2, k + 0, block, 0);
		this.setBlock(world, i + 3, j + 2, k + 1, Blocks.air, 0);
		this.setBlock(world, i + 3, j + 2, k + 2, Blocks.air, 0);
		this.setBlock(world, i + 3, j + 2, k + 3, Blocks.air, 0);
		this.setBlock(world, i + 3, j + 2, k + 4, Blocks.air, 0);
		this.setBlock(world, i + 3, j + 2, k + 5, block, 0);
		this.setBlock(world, i + 3, j + 2, k + 6, block, 0);
		this.setBlock(world, i + 3, j + 2, k + 7, block, 0);
		this.setBlock(world, i + 3, j + 2, k + 8, block, 0);
		this.setBlock(world, i + 3, j + 2, k + 9, Blocks.air, 0);
		this.setBlock(world, i + 3, j + 2, k + 10, block, 0);
		this.setBlock(world, i + 3, j + 2, k + 11, block, 0);
		this.setBlock(world, i + 3, j + 2, k + 12, block, 0);
		this.setBlock(world, i + 3, j + 3, k + 0, block, 0);
		this.setBlock(world, i + 3, j + 3, k + 1, Blocks.air, 0);
		this.setBlock(world, i + 3, j + 3, k + 2, Blocks.air, 0);
		this.setBlock(world, i + 3, j + 3, k + 3, Blocks.air, 0);
		this.setBlock(world, i + 3, j + 3, k + 4, Blocks.air, 0);
		this.setBlock(world, i + 3, j + 3, k + 5, block, 0);
		this.setBlock(world, i + 3, j + 3, k + 6, block, 0);
		this.setBlock(world, i + 3, j + 3, k + 7, block, 0);
		this.setBlock(world, i + 3, j + 3, k + 8, block, 0);
		this.setBlock(world, i + 3, j + 3, k + 9, block, 0);
		this.setBlock(world, i + 3, j + 3, k + 10, block, 0);
		this.setBlock(world, i + 3, j + 3, k + 11, block, 0);
		this.setBlock(world, i + 3, j + 3, k + 12, block, 0);
		this.setBlock(world, i + 3, j + 4, k + 0, block, 0);
		this.setBlock(world, i + 3, j + 4, k + 1, block, 0);
		this.setBlock(world, i + 3, j + 4, k + 2, block, 0);
		this.setBlock(world, i + 3, j + 4, k + 3, block, 0);
		this.setBlock(world, i + 3, j + 4, k + 4, block, 0);
		this.setBlock(world, i + 3, j + 4, k + 5, block, 0);
		this.setBlock(world, i + 3, j + 4, k + 6, block, 0);
		this.setBlock(world, i + 3, j + 4, k + 7, block, 0);
		this.setBlock(world, i + 3, j + 4, k + 8, block, 0);
		this.setBlock(world, i + 3, j + 4, k + 9, block, 0);
		this.setBlock(world, i + 3, j + 4, k + 10, block, 0);
		this.setBlock(world, i + 3, j + 4, k + 11, block, 0);
		this.setBlock(world, i + 3, j + 4, k + 12, block, 0);
		this.setBlock(world, i + 4, j + 0, k + 0, block, 0);
		this.setBlock(world, i + 4, j + 0, k + 1, block, 0);
		this.setBlock(world, i + 4, j + 0, k + 2, block, 0);
		this.setBlock(world, i + 4, j + 0, k + 3, block, 0);
		this.setBlock(world, i + 4, j + 0, k + 4, block, 0);
		this.setBlock(world, i + 4, j + 0, k + 5, block, 0);
		this.setBlock(world, i + 4, j + 0, k + 6, block, 0);
		this.setBlock(world, i + 4, j + 0, k + 7, block, 0);
		this.setBlock(world, i + 4, j + 0, k + 8, block, 0);
		this.setBlock(world, i + 4, j + 0, k + 9, block, 0);
		this.setBlock(world, i + 4, j + 0, k + 10, block, 0);
		this.setBlock(world, i + 4, j + 0, k + 11, block, 0);
		this.setBlock(world, i + 4, j + 0, k + 12, block, 0);
		this.setBlock(world, i + 4, j + 1, k + 0, block, 0);
		this.setBlock(world, i + 4, j + 1, k + 1, Blocks.air, 0);
		this.setBlock(world, i + 4, j + 1, k + 2, Blocks.air, 0);
		this.setBlock(world, i + 4, j + 1, k + 3, Blocks.air, 0);
		this.setBlock(world, i + 4, j + 1, k + 4, Blocks.air, 0);
		this.setBlock(world, i + 4, j + 1, k + 5, block, 0);
		this.setBlock(world, i + 4, j + 1, k + 6, Blocks.air, 0);
		this.setBlock(world, i + 4, j + 1, k + 7, Blocks.air, 0);
		this.setBlock(world, i + 4, j + 1, k + 8, Blocks.air, 0);
		this.setBlock(world, i + 4, j + 1, k + 9, Blocks.air, 0);
		this.setBlock(world, i + 4, j + 1, k + 10, Blocks.air, 0);
		this.setBlock(world, i + 4, j + 1, k + 11, Blocks.air, 0);
		this.setBlock(world, i + 4, j + 1, k + 12, block, 0);
		this.setBlock(world, i + 4, j + 2, k + 0, block, 0);
		this.setBlock(world, i + 4, j + 2, k + 1, Blocks.air, 0);
		this.setBlock(world, i + 4, j + 2, k + 2, Blocks.air, 0);
		this.setBlock(world, i + 4, j + 2, k + 3, Blocks.air, 0);
		this.setBlock(world, i + 4, j + 2, k + 4, Blocks.air, 0);
		this.setBlock(world, i + 4, j + 2, k + 5, block, 0);
		this.setBlock(world, i + 4, j + 2, k + 6, Blocks.air, 0);
		this.setBlock(world, i + 4, j + 2, k + 7, Blocks.air, 0);
		this.setBlock(world, i + 4, j + 2, k + 8, Blocks.air, 0);
		this.setBlock(world, i + 4, j + 2, k + 9, Blocks.air, 0);
		this.setBlock(world, i + 4, j + 2, k + 10, Blocks.air, 0);
		this.setBlock(world, i + 4, j + 2, k + 11, Blocks.air, 0);
		this.setBlock(world, i + 4, j + 2, k + 12, block, 0);
		this.setBlock(world, i + 4, j + 3, k + 0, block, 0);
		this.setBlock(world, i + 4, j + 3, k + 1, Blocks.air, 0);
		this.setBlock(world, i + 4, j + 3, k + 2, Blocks.air, 0);
		this.setBlock(world, i + 4, j + 3, k + 3, Blocks.air, 0);
		this.setBlock(world, i + 4, j + 3, k + 4, Blocks.air, 0);
		this.setBlock(world, i + 4, j + 3, k + 5, block, 0);
		this.setBlock(world, i + 4, j + 3, k + 6, Blocks.air, 0);
		this.setBlock(world, i + 4, j + 3, k + 7, Blocks.air, 0);
		this.setBlock(world, i + 4, j + 3, k + 8, Blocks.air, 0);
		this.setBlock(world, i + 4, j + 3, k + 9, Blocks.air, 0);
		this.setBlock(world, i + 4, j + 3, k + 10, Blocks.air, 0);
		this.setBlock(world, i + 4, j + 3, k + 11, Blocks.air, 0);
		this.setBlock(world, i + 4, j + 3, k + 12, block, 0);
		this.setBlock(world, i + 4, j + 4, k + 0, block, 0);
		this.setBlock(world, i + 4, j + 4, k + 1, block, 0);
		this.setBlock(world, i + 4, j + 4, k + 2, block, 0);
		this.setBlock(world, i + 4, j + 4, k + 3, block, 0);
		this.setBlock(world, i + 4, j + 4, k + 4, block, 0);
		this.setBlock(world, i + 4, j + 4, k + 5, block, 0);
		this.setBlock(world, i + 4, j + 4, k + 6, block, 0);
		this.setBlock(world, i + 4, j + 4, k + 7, block, 0);
		this.setBlock(world, i + 4, j + 4, k + 8, block, 0);
		this.setBlock(world, i + 4, j + 4, k + 9, block, 0);
		this.setBlock(world, i + 4, j + 4, k + 10, block, 0);
		this.setBlock(world, i + 4, j + 4, k + 11, block, 0);
		this.setBlock(world, i + 4, j + 4, k + 12, block, 0);
		this.setBlock(world, i + 5, j + 0, k + 0, block, 0);
		this.setBlock(world, i + 5, j + 0, k + 1, block, 0);
		this.setBlock(world, i + 5, j + 0, k + 2, block, 0);
		this.setBlock(world, i + 5, j + 0, k + 3, block, 0);
		this.setBlock(world, i + 5, j + 0, k + 4, block, 0);
		this.setBlock(world, i + 5, j + 0, k + 5, block, 0);
		this.setBlock(world, i + 5, j + 0, k + 6, block, 0);
		this.setBlock(world, i + 5, j + 0, k + 7, block, 0);
		this.setBlock(world, i + 5, j + 0, k + 8, block, 0);
		this.setBlock(world, i + 5, j + 0, k + 9, block, 0);
		this.setBlock(world, i + 5, j + 0, k + 10, block, 0);
		this.setBlock(world, i + 5, j + 0, k + 11, block, 0);
		this.setBlock(world, i + 5, j + 0, k + 12, block, 0);
		this.setBlock(world, i + 5, j + 1, k + 0, block, 0);
		this.setBlock(world, i + 5, j + 1, k + 1, Blocks.air, 0);
		this.setBlock(world, i + 5, j + 1, k + 2, Blocks.air, 0);
		this.setBlock(world, i + 5, j + 1, k + 3, Blocks.air, 0);
		this.setBlock(world, i + 5, j + 1, k + 4, Blocks.air, 0);
		this.setBlock(world, i + 5, j + 1, k + 5, block, 0);
		this.setBlock(world, i + 5, j + 1, k + 6, Blocks.air, 0);
		this.setBlock(world, i + 5, j + 1, k + 7, Blocks.air, 0);
		this.setBlock(world, i + 5, j + 1, k + 8, Blocks.air, 0);
		this.setBlock(world, i + 5, j + 1, k + 9, Blocks.air, 0);
		this.setBlock(world, i + 5, j + 1, k + 10, Blocks.air, 0);
		this.setBlock(world, i + 5, j + 1, k + 11, Blocks.air, 0);
		this.setBlock(world, i + 5, j + 1, k + 12, block, 0);
		this.setBlock(world, i + 5, j + 2, k + 0, block, 0);
		this.setBlock(world, i + 5, j + 2, k + 1, Blocks.air, 0);
		this.setBlock(world, i + 5, j + 2, k + 2, Blocks.air, 0);
		this.setBlock(world, i + 5, j + 2, k + 3, Blocks.air, 0);
		this.setBlock(world, i + 5, j + 2, k + 4, Blocks.air, 0);
		this.setBlock(world, i + 5, j + 2, k + 5, block, 0);
		this.setBlock(world, i + 5, j + 2, k + 6, Blocks.air, 0);
		this.setBlock(world, i + 5, j + 2, k + 7, Blocks.air, 0);
		this.setBlock(world, i + 5, j + 2, k + 8, Blocks.air, 0);
		this.setBlock(world, i + 5, j + 2, k + 9, Blocks.air, 0);
		this.setBlock(world, i + 5, j + 2, k + 10, Blocks.air, 0);
		this.setBlock(world, i + 5, j + 2, k + 11, Blocks.air, 0);
		this.setBlock(world, i + 5, j + 2, k + 12, block, 0);
		this.setBlock(world, i + 5, j + 3, k + 0, block, 0);
		this.setBlock(world, i + 5, j + 3, k + 1, Blocks.air, 0);
		this.setBlock(world, i + 5, j + 3, k + 2, Blocks.air, 0);
		this.setBlock(world, i + 5, j + 3, k + 3, Blocks.air, 0);
		this.setBlock(world, i + 5, j + 3, k + 4, Blocks.air, 0);
		this.setBlock(world, i + 5, j + 3, k + 5, block, 0);
		this.setBlock(world, i + 5, j + 3, k + 6, Blocks.air, 0);
		this.setBlock(world, i + 5, j + 3, k + 7, Blocks.air, 0);
		this.setBlock(world, i + 5, j + 3, k + 8, Blocks.air, 0);
		this.setBlock(world, i + 5, j + 3, k + 9, Blocks.air, 0);
		this.setBlock(world, i + 5, j + 3, k + 10, Blocks.air, 0);
		this.setBlock(world, i + 5, j + 3, k + 11, Blocks.air, 0);
		this.setBlock(world, i + 5, j + 3, k + 12, block, 0);
		this.setBlock(world, i + 5, j + 4, k + 0, block, 0);
		this.setBlock(world, i + 5, j + 4, k + 1, block, 0);
		this.setBlock(world, i + 5, j + 4, k + 2, block, 0);
		this.setBlock(world, i + 5, j + 4, k + 3, block, 0);
		this.setBlock(world, i + 5, j + 4, k + 4, block, 0);
		this.setBlock(world, i + 5, j + 4, k + 5, block, 0);
		this.setBlock(world, i + 5, j + 4, k + 6, block, 0);
		this.setBlock(world, i + 5, j + 4, k + 7, block, 0);
		this.setBlock(world, i + 5, j + 4, k + 8, block, 0);
		this.setBlock(world, i + 5, j + 4, k + 9, block, 0);
		this.setBlock(world, i + 5, j + 4, k + 10, block, 0);
		this.setBlock(world, i + 5, j + 4, k + 11, block, 0);
		this.setBlock(world, i + 5, j + 4, k + 12, block, 0);
		this.setBlock(world, i + 6, j + 0, k + 0, block, 0);
		this.setBlock(world, i + 6, j + 0, k + 1, block, 0);
		this.setBlock(world, i + 6, j + 0, k + 2, block, 0);
		this.setBlock(world, i + 6, j + 0, k + 3, block, 0);
		this.setBlock(world, i + 6, j + 0, k + 4, block, 0);
		this.setBlock(world, i + 6, j + 0, k + 5, block, 0);
		this.setBlock(world, i + 6, j + 0, k + 6, block, 0);
		this.setBlock(world, i + 6, j + 0, k + 7, block, 0);
		this.setBlock(world, i + 6, j + 0, k + 8, block, 0);
		this.setBlock(world, i + 6, j + 0, k + 9, block, 0);
		this.setBlock(world, i + 6, j + 0, k + 10, block, 0);
		this.setBlock(world, i + 6, j + 0, k + 11, block, 0);
		this.setBlock(world, i + 6, j + 0, k + 12, block, 0);
		this.setBlock(world, i + 6, j + 1, k + 0, block, 0);
		this.setBlock(world, i + 6, j + 1, k + 1, Blocks.air, 0);
		this.setBlock(world, i + 6, j + 1, k + 2, Blocks.air, 0);
		this.setBlock(world, i + 6, j + 1, k + 3, Blocks.air, 0);
		this.setBlock(world, i + 6, j + 1, k + 4, Blocks.air, 0);
		this.setBlock(world, i + 6, j + 1, k + 5, Blocks.air, 0);
		this.setBlock(world, i + 6, j + 1, k + 6, Blocks.air, 0);
		this.setBlock(world, i + 6, j + 1, k + 7, Blocks.air, 0);
		this.setBlock(world, i + 6, j + 1, k + 8, Blocks.air, 0);
		this.setBlock(world, i + 6, j + 1, k + 9, Blocks.air, 0);
		this.setBlock(world, i + 6, j + 1, k + 10, Blocks.air, 0);
		this.setBlock(world, i + 6, j + 1, k + 11, Blocks.air, 0);
		this.setBlock(world, i + 6, j + 1, k + 12, block, 0);
		this.setBlock(world, i + 6, j + 2, k + 0, block, 0);
		this.setBlock(world, i + 6, j + 2, k + 1, Blocks.air, 0);
		this.setBlock(world, i + 6, j + 2, k + 2, Blocks.air, 0);
		this.setBlock(world, i + 6, j + 2, k + 3, Blocks.air, 0);
		this.setBlock(world, i + 6, j + 2, k + 4, Blocks.air, 0);
		this.setBlock(world, i + 6, j + 2, k + 5, Blocks.air, 0);
		this.setBlock(world, i + 6, j + 2, k + 6, Blocks.air, 0);
		this.setBlock(world, i + 6, j + 2, k + 7, Blocks.air, 0);
		this.setBlock(world, i + 6, j + 2, k + 8, Blocks.air, 0);
		this.setBlock(world, i + 6, j + 2, k + 9, Blocks.air, 0);
		this.setBlock(world, i + 6, j + 2, k + 10, Blocks.air, 0);
		this.setBlock(world, i + 6, j + 2, k + 11, Blocks.air, 0);
		this.setBlock(world, i + 6, j + 2, k + 12, block, 0);
		this.setBlock(world, i + 6, j + 3, k + 0, block, 0);
		this.setBlock(world, i + 6, j + 3, k + 1, Blocks.air, 0);
		this.setBlock(world, i + 6, j + 3, k + 2, Blocks.air, 0);
		this.setBlock(world, i + 6, j + 3, k + 3, Blocks.air, 0);
		this.setBlock(world, i + 6, j + 3, k + 4, Blocks.air, 0);
		this.setBlock(world, i + 6, j + 3, k + 5, block, 0);
		this.setBlock(world, i + 6, j + 3, k + 6, Blocks.air, 0);
		this.setBlock(world, i + 6, j + 3, k + 7, Blocks.air, 0);
		this.setBlock(world, i + 6, j + 3, k + 8, Blocks.air, 0);
		this.setBlock(world, i + 6, j + 3, k + 9, Blocks.air, 0);
		this.setBlock(world, i + 6, j + 3, k + 10, Blocks.air, 0);
		this.setBlock(world, i + 6, j + 3, k + 11, Blocks.air, 0);
		this.setBlock(world, i + 6, j + 3, k + 12, block, 0);
		this.setBlock(world, i + 6, j + 4, k + 0, block, 0);
		this.setBlock(world, i + 6, j + 4, k + 1, block, 0);
		this.setBlock(world, i + 6, j + 4, k + 2, block, 0);
		this.setBlock(world, i + 6, j + 4, k + 3, block, 0);
		this.setBlock(world, i + 6, j + 4, k + 4, block, 0);
		this.setBlock(world, i + 6, j + 4, k + 5, block, 0);
		this.setBlock(world, i + 6, j + 4, k + 6, block, 0);
		this.setBlock(world, i + 6, j + 4, k + 7, block, 0);
		this.setBlock(world, i + 6, j + 4, k + 8, block, 0);
		this.setBlock(world, i + 6, j + 4, k + 9, block, 0);
		this.setBlock(world, i + 6, j + 4, k + 10, block, 0);
		this.setBlock(world, i + 6, j + 4, k + 11, block, 0);
		this.setBlock(world, i + 6, j + 4, k + 12, block, 0);
		this.setBlock(world, i + 7, j + 0, k + 0, block, 0);
		this.setBlock(world, i + 7, j + 0, k + 1, block, 0);
		this.setBlock(world, i + 7, j + 0, k + 2, block, 0);
		this.setBlock(world, i + 7, j + 0, k + 3, block, 0);
		this.setBlock(world, i + 7, j + 0, k + 4, block, 0);
		this.setBlock(world, i + 7, j + 0, k + 5, block, 0);
		this.setBlock(world, i + 7, j + 0, k + 6, block, 0);
		this.setBlock(world, i + 7, j + 0, k + 7, block, 0);
		this.setBlock(world, i + 7, j + 0, k + 8, block, 0);
		this.setBlock(world, i + 7, j + 0, k + 9, block, 0);
		this.setBlock(world, i + 7, j + 0, k + 10, block, 0);
		this.setBlock(world, i + 7, j + 0, k + 11, block, 0);
		this.setBlock(world, i + 7, j + 0, k + 12, block, 0);
		this.setBlock(world, i + 7, j + 1, k + 0, block, 0);
		this.setBlock(world, i + 7, j + 1, k + 1, Blocks.air, 0);
		this.setBlock(world, i + 7, j + 1, k + 2, Blocks.air, 0);
		this.setBlock(world, i + 7, j + 1, k + 3, Blocks.air, 0);
		this.setBlock(world, i + 7, j + 1, k + 4, Blocks.air, 0);
		this.setBlock(world, i + 7, j + 1, k + 5, block, 0);
		this.setBlock(world, i + 7, j + 1, k + 6, Blocks.air, 0);
		this.setBlock(world, i + 7, j + 1, k + 7, Blocks.air, 0);
		this.setBlock(world, i + 7, j + 1, k + 8, Blocks.air, 0);
		this.setBlock(world, i + 7, j + 1, k + 9, Blocks.air, 0);
		this.setBlock(world, i + 7, j + 1, k + 10, Blocks.air, 0);
		this.setBlock(world, i + 7, j + 1, k + 11, Blocks.air, 0);
		this.setBlock(world, i + 7, j + 1, k + 12, block, 0);
		this.setBlock(world, i + 7, j + 2, k + 0, block, 0);
		this.setBlock(world, i + 7, j + 2, k + 1, Blocks.air, 0);
		this.setBlock(world, i + 7, j + 2, k + 2, Blocks.air, 0);
		this.setBlock(world, i + 7, j + 2, k + 3, Blocks.air, 0);
		this.setBlock(world, i + 7, j + 2, k + 4, Blocks.air, 0);
		this.setBlock(world, i + 7, j + 2, k + 5, block, 0);
		this.setBlock(world, i + 7, j + 2, k + 6, Blocks.air, 0);
		this.setBlock(world, i + 7, j + 2, k + 7, Blocks.air, 0);
		this.setBlock(world, i + 7, j + 2, k + 8, Blocks.air, 0);
		this.setBlock(world, i + 7, j + 2, k + 9, Blocks.air, 0);
		this.setBlock(world, i + 7, j + 2, k + 10, Blocks.air, 0);
		this.setBlock(world, i + 7, j + 2, k + 11, Blocks.air, 0);
		this.setBlock(world, i + 7, j + 2, k + 12, block, 0);
		this.setBlock(world, i + 7, j + 3, k + 0, block, 0);
		this.setBlock(world, i + 7, j + 3, k + 1, Blocks.air, 0);
		this.setBlock(world, i + 7, j + 3, k + 2, Blocks.air, 0);
		this.setBlock(world, i + 7, j + 3, k + 3, Blocks.air, 0);
		this.setBlock(world, i + 7, j + 3, k + 4, Blocks.air, 0);
		this.setBlock(world, i + 7, j + 3, k + 5, block, 0);
		this.setBlock(world, i + 7, j + 3, k + 6, Blocks.air, 0);
		this.setBlock(world, i + 7, j + 3, k + 7, Blocks.air, 0);
		this.setBlock(world, i + 7, j + 3, k + 8, Blocks.air, 0);
		this.setBlock(world, i + 7, j + 3, k + 9, Blocks.air, 0);
		this.setBlock(world, i + 7, j + 3, k + 10, Blocks.air, 0);
		this.setBlock(world, i + 7, j + 3, k + 11, Blocks.air, 0);
		this.setBlock(world, i + 7, j + 3, k + 12, block, 0);
		this.setBlock(world, i + 7, j + 4, k + 0, block, 0);
		this.setBlock(world, i + 7, j + 4, k + 1, block, 0);
		this.setBlock(world, i + 7, j + 4, k + 2, block, 0);
		this.setBlock(world, i + 7, j + 4, k + 3, block, 0);
		this.setBlock(world, i + 7, j + 4, k + 4, block, 0);
		this.setBlock(world, i + 7, j + 4, k + 5, block, 0);
		this.setBlock(world, i + 7, j + 4, k + 6, block, 0);
		this.setBlock(world, i + 7, j + 4, k + 7, block, 0);
		this.setBlock(world, i + 7, j + 4, k + 8, block, 0);
		this.setBlock(world, i + 7, j + 4, k + 9, block, 0);
		this.setBlock(world, i + 7, j + 4, k + 10, block, 0);
		this.setBlock(world, i + 7, j + 4, k + 11, block, 0);
		this.setBlock(world, i + 7, j + 4, k + 12, block, 0);
		this.setBlock(world, i + 8, j + 0, k + 0, block, 0);
		this.setBlock(world, i + 8, j + 0, k + 1, block, 0);
		this.setBlock(world, i + 8, j + 0, k + 2, block, 0);
		this.setBlock(world, i + 8, j + 0, k + 3, block, 0);
		this.setBlock(world, i + 8, j + 0, k + 4, block, 0);
		this.setBlock(world, i + 8, j + 0, k + 5, block, 0);
		this.setBlock(world, i + 8, j + 0, k + 6, block, 0);
		this.setBlock(world, i + 8, j + 0, k + 7, block, 0);
		this.setBlock(world, i + 8, j + 0, k + 8, block, 0);
		this.setBlock(world, i + 8, j + 0, k + 9, block, 0);
		this.setBlock(world, i + 8, j + 0, k + 10, block, 0);
		this.setBlock(world, i + 8, j + 0, k + 11, block, 0);
		this.setBlock(world, i + 8, j + 0, k + 12, block, 0);
		this.setBlock(world, i + 8, j + 1, k + 0, block, 0);
		this.setBlock(world, i + 8, j + 1, k + 1, Blocks.air, 0);
		this.setBlock(world, i + 8, j + 1, k + 2, Blocks.air, 0);
		this.setBlock(world, i + 8, j + 1, k + 3, Blocks.air, 0);
		this.setBlock(world, i + 8, j + 1, k + 4, Blocks.air, 0);
		this.setBlock(world, i + 8, j + 1, k + 5, block, 0);
		this.setBlock(world, i + 8, j + 1, k + 6, Blocks.air, 0);
		this.setBlock(world, i + 8, j + 1, k + 7, Blocks.air, 0);
		this.setBlock(world, i + 8, j + 1, k + 8, Blocks.air, 0);
		this.setBlock(world, i + 8, j + 1, k + 9, Blocks.air, 0);
		this.setBlock(world, i + 8, j + 1, k + 10, Blocks.air, 0);
		this.setBlock(world, i + 8, j + 1, k + 11, Blocks.air, 0);
		this.setBlock(world, i + 8, j + 1, k + 12, block, 0);
		this.setBlock(world, i + 8, j + 2, k + 0, block, 0);
		this.setBlock(world, i + 8, j + 2, k + 1, Blocks.air, 0);
		this.setBlock(world, i + 8, j + 2, k + 2, Blocks.air, 0);
		this.setBlock(world, i + 8, j + 2, k + 3, Blocks.air, 0);
		this.setBlock(world, i + 8, j + 2, k + 4, Blocks.air, 0);
		this.setBlock(world, i + 8, j + 2, k + 5, block, 0);
		this.setBlock(world, i + 8, j + 2, k + 6, Blocks.air, 0);
		this.setBlock(world, i + 8, j + 2, k + 7, Blocks.air, 0);
		this.setBlock(world, i + 8, j + 2, k + 8, Blocks.air, 0);
		this.setBlock(world, i + 8, j + 2, k + 9, Blocks.air, 0);
		this.setBlock(world, i + 8, j + 2, k + 10, Blocks.air, 0);
		this.setBlock(world, i + 8, j + 2, k + 11, Blocks.air, 0);
		this.setBlock(world, i + 8, j + 2, k + 12, block, 0);
		this.setBlock(world, i + 8, j + 3, k + 0, block, 0);
		this.setBlock(world, i + 8, j + 3, k + 1, Blocks.air, 0);
		this.setBlock(world, i + 8, j + 3, k + 2, Blocks.air, 0);
		this.setBlock(world, i + 8, j + 3, k + 3, Blocks.air, 0);
		this.setBlock(world, i + 8, j + 3, k + 4, Blocks.air, 0);
		this.setBlock(world, i + 8, j + 3, k + 5, block, 0);
		this.setBlock(world, i + 8, j + 3, k + 6, Blocks.air, 0);
		this.setBlock(world, i + 8, j + 3, k + 7, Blocks.air, 0);
		this.setBlock(world, i + 8, j + 3, k + 8, Blocks.air, 0);
		this.setBlock(world, i + 8, j + 3, k + 9, Blocks.air, 0);
		this.setBlock(world, i + 8, j + 3, k + 10, Blocks.air, 0);
		this.setBlock(world, i + 8, j + 3, k + 11, Blocks.air, 0);
		this.setBlock(world, i + 8, j + 3, k + 12, block, 0);
		this.setBlock(world, i + 8, j + 4, k + 0, block, 0);
		this.setBlock(world, i + 8, j + 4, k + 1, block, 0);
		this.setBlock(world, i + 8, j + 4, k + 2, block, 0);
		this.setBlock(world, i + 8, j + 4, k + 3, block, 0);
		this.setBlock(world, i + 8, j + 4, k + 4, block, 0);
		this.setBlock(world, i + 8, j + 4, k + 5, block, 0);
		this.setBlock(world, i + 8, j + 4, k + 6, block, 0);
		this.setBlock(world, i + 8, j + 4, k + 7, block, 0);
		this.setBlock(world, i + 8, j + 4, k + 8, block, 0);
		this.setBlock(world, i + 8, j + 4, k + 9, block, 0);
		this.setBlock(world, i + 8, j + 4, k + 10, block, 0);
		this.setBlock(world, i + 8, j + 4, k + 11, block, 0);
		this.setBlock(world, i + 8, j + 4, k + 12, block, 0);
		this.setBlock(world, i + 9, j + 0, k + 0, block, 0);
		this.setBlock(world, i + 9, j + 0, k + 1, block, 0);
		this.setBlock(world, i + 9, j + 0, k + 2, block, 0);
		this.setBlock(world, i + 9, j + 0, k + 3, block, 0);
		this.setBlock(world, i + 9, j + 0, k + 4, block, 0);
		this.setBlock(world, i + 9, j + 0, k + 5, block, 0);
		this.setBlock(world, i + 9, j + 0, k + 6, block, 0);
		this.setBlock(world, i + 9, j + 0, k + 7, block, 0);
		this.setBlock(world, i + 9, j + 0, k + 8, block, 0);
		this.setBlock(world, i + 9, j + 0, k + 9, block, 0);
		this.setBlock(world, i + 9, j + 0, k + 10, block, 0);
		this.setBlock(world, i + 9, j + 0, k + 11, block, 0);
		this.setBlock(world, i + 9, j + 0, k + 12, block, 0);
		this.setBlock(world, i + 9, j + 1, k + 0, block, 0);
		this.setBlock(world, i + 9, j + 1, k + 1, block, 0);
		this.setBlock(world, i + 9, j + 1, k + 2, block, 0);
		this.setBlock(world, i + 9, j + 1, k + 3, block, 0);
		this.setBlock(world, i + 9, j + 1, k + 4, block, 0);
		this.setBlock(world, i + 9, j + 1, k + 5, block, 0);
		this.setBlock(world, i + 9, j + 1, k + 6, block, 0);
		this.setBlock(world, i + 9, j + 1, k + 7, block, 0);
		this.setBlock(world, i + 9, j + 1, k + 8, block, 0);
		this.setBlock(world, i + 9, j + 1, k + 9, block, 0);
		this.setBlock(world, i + 9, j + 1, k + 10, block, 0);
		this.setBlock(world, i + 9, j + 1, k + 11, block, 0);
		this.setBlock(world, i + 9, j + 1, k + 12, block, 0);
		this.setBlock(world, i + 9, j + 2, k + 0, block, 0);
		this.setBlock(world, i + 9, j + 2, k + 1, block, 0);
		this.setBlock(world, i + 9, j + 2, k + 2, block, 0);
		this.setBlock(world, i + 9, j + 2, k + 3, block, 0);
		this.setBlock(world, i + 9, j + 2, k + 4, block, 0);
		this.setBlock(world, i + 9, j + 2, k + 5, block, 0);
		this.setBlock(world, i + 9, j + 2, k + 6, block, 0);
		this.setBlock(world, i + 9, j + 2, k + 7, block, 0);
		this.setBlock(world, i + 9, j + 2, k + 8, block, 0);
		this.setBlock(world, i + 9, j + 2, k + 9, block, 0);
		this.setBlock(world, i + 9, j + 2, k + 10, block, 0);
		this.setBlock(world, i + 9, j + 2, k + 11, block, 0);
		this.setBlock(world, i + 9, j + 2, k + 12, block, 0);
		this.setBlock(world, i + 9, j + 3, k + 0, block, 0);
		this.setBlock(world, i + 9, j + 3, k + 1, block, 0);
		this.setBlock(world, i + 9, j + 3, k + 2, block, 0);
		this.setBlock(world, i + 9, j + 3, k + 3, block, 0);
		this.setBlock(world, i + 9, j + 3, k + 4, block, 0);
		this.setBlock(world, i + 9, j + 3, k + 5, block, 0);
		this.setBlock(world, i + 9, j + 3, k + 6, block, 0);
		this.setBlock(world, i + 9, j + 3, k + 7, block, 0);
		this.setBlock(world, i + 9, j + 3, k + 8, block, 0);
		this.setBlock(world, i + 9, j + 3, k + 9, block, 0);
		this.setBlock(world, i + 9, j + 3, k + 10, block, 0);
		this.setBlock(world, i + 9, j + 3, k + 11, block, 0);
		this.setBlock(world, i + 9, j + 3, k + 12, block, 0);
		this.setBlock(world, i + 9, j + 4, k + 0, block, 0);
		this.setBlock(world, i + 9, j + 4, k + 1, block, 0);
		this.setBlock(world, i + 9, j + 4, k + 2, block, 0);
		this.setBlock(world, i + 9, j + 4, k + 3, block, 0);
		this.setBlock(world, i + 9, j + 4, k + 4, block, 0);
		this.setBlock(world, i + 9, j + 4, k + 5, block, 0);
		this.setBlock(world, i + 9, j + 4, k + 6, block, 0);
		this.setBlock(world, i + 9, j + 4, k + 7, block, 0);
		this.setBlock(world, i + 9, j + 4, k + 8, block, 0);
		this.setBlock(world, i + 9, j + 4, k + 9, block, 0);
		this.setBlock(world, i + 9, j + 4, k + 10, block, 0);
		this.setBlock(world, i + 9, j + 4, k + 11, block, 0);
		this.setBlock(world, i + 9, j + 4, k + 12, block, 0);

		return true;
	}
}