package ebm.com.mce.gen.feature;

import java.util.Random;

import cpw.mods.fml.common.IWorldGenerator;
import net.minecraft.block.Block;
import net.minecraft.init.Blocks;
import net.minecraft.world.World;
import net.minecraft.world.chunk.IChunkProvider;
import net.minecraft.world.gen.feature.WorldGenerator;

public class WorldGenAutilLab3 extends WorldGenerator implements IWorldGenerator {
	public static Block block, slabBlock, stairBlock;

	public WorldGenAutilLab3() {
	}

	@Override
	public void generate(Random random, int chunkX, int chunkZ, World world, IChunkProvider chunkGenerator,
			IChunkProvider chunkProvider) {
	}

	public void setBlock(World world, int x, int y, int z, Block block, int metadata) {
		Block b1 = world.getBlock(x, y, z);

		if (b1.isAir(world, x, y, z) || b1.isLeaves(world, x, y, z)) {
			world.setBlock(x, y, z, block, metadata, 2);
		}
	}

	public boolean generate(World world, Random rand, int i, int j, int k) {
		this.setBlock(world, i + 0, j + 1, k + 43, slabBlock, 8);
		this.setBlock(world, i + 0, j + 1, k + 44, block, 0);
		this.setBlock(world, i + 0, j + 1, k + 45, block, 0);
		this.setBlock(world, i + 0, j + 1, k + 46, block, 0);
		this.setBlock(world, i + 0, j + 1, k + 47, block, 0);
		this.setBlock(world, i + 0, j + 1, k + 48, block, 0);
		this.setBlock(world, i + 0, j + 1, k + 49, block, 0);
		this.setBlock(world, i + 0, j + 1, k + 50, block, 0);
		this.setBlock(world, i + 0, j + 1, k + 51, block, 0);
		this.setBlock(world, i + 0, j + 1, k + 52, block, 0);
		this.setBlock(world, i + 0, j + 1, k + 53, block, 0);
		this.setBlock(world, i + 0, j + 1, k + 54, block, 0);
		this.setBlock(world, i + 0, j + 1, k + 55, block, 0);
		this.setBlock(world, i + 0, j + 1, k + 56, block, 0);
		this.setBlock(world, i + 0, j + 1, k + 57, block, 0);
		this.setBlock(world, i + 0, j + 1, k + 58, block, 0);
		this.setBlock(world, i + 0, j + 1, k + 59, slabBlock, 8);
		this.setBlock(world, i + 0, j + 2, k + 43, block, 0);
		this.setBlock(world, i + 0, j + 2, k + 44, block, 0);
		this.setBlock(world, i + 0, j + 2, k + 45, block, 0);
		this.setBlock(world, i + 0, j + 2, k + 46, block, 0);
		this.setBlock(world, i + 0, j + 2, k + 47, block, 0);
		this.setBlock(world, i + 0, j + 2, k + 48, block, 0);
		this.setBlock(world, i + 0, j + 2, k + 49, block, 0);
		this.setBlock(world, i + 0, j + 2, k + 50, block, 0);
		this.setBlock(world, i + 0, j + 2, k + 51, block, 0);
		this.setBlock(world, i + 0, j + 2, k + 52, block, 0);
		this.setBlock(world, i + 0, j + 2, k + 53, block, 0);
		this.setBlock(world, i + 0, j + 2, k + 54, block, 0);
		this.setBlock(world, i + 0, j + 2, k + 55, block, 0);
		this.setBlock(world, i + 0, j + 2, k + 56, block, 0);
		this.setBlock(world, i + 0, j + 2, k + 57, block, 0);
		this.setBlock(world, i + 0, j + 2, k + 58, block, 0);
		this.setBlock(world, i + 0, j + 2, k + 59, block, 0);
		this.setBlock(world, i + 0, j + 3, k + 43, block, 0);
		this.setBlock(world, i + 0, j + 3, k + 44, block, 0);
		this.setBlock(world, i + 0, j + 3, k + 45, block, 0);
		this.setBlock(world, i + 0, j + 3, k + 46, block, 0);
		this.setBlock(world, i + 0, j + 3, k + 47, block, 0);
		this.setBlock(world, i + 0, j + 3, k + 48, block, 0);
		this.setBlock(world, i + 0, j + 3, k + 49, block, 0);
		this.setBlock(world, i + 0, j + 3, k + 50, block, 0);
		this.setBlock(world, i + 0, j + 3, k + 51, block, 0);
		this.setBlock(world, i + 0, j + 3, k + 52, block, 0);
		this.setBlock(world, i + 0, j + 3, k + 53, block, 0);
		this.setBlock(world, i + 0, j + 3, k + 54, block, 0);
		this.setBlock(world, i + 0, j + 3, k + 55, block, 0);
		this.setBlock(world, i + 0, j + 3, k + 56, block, 0);
		this.setBlock(world, i + 0, j + 3, k + 57, block, 0);
		this.setBlock(world, i + 0, j + 3, k + 58, block, 0);
		this.setBlock(world, i + 0, j + 3, k + 59, block, 0);
		this.setBlock(world, i + 0, j + 4, k + 43, block, 0);
		this.setBlock(world, i + 0, j + 4, k + 44, block, 0);
		this.setBlock(world, i + 0, j + 4, k + 45, block, 0);
		this.setBlock(world, i + 0, j + 4, k + 46, block, 0);
		this.setBlock(world, i + 0, j + 4, k + 47, block, 0);
		this.setBlock(world, i + 0, j + 4, k + 48, block, 0);
		this.setBlock(world, i + 0, j + 4, k + 49, block, 0);
		this.setBlock(world, i + 0, j + 4, k + 50, block, 0);
		this.setBlock(world, i + 0, j + 4, k + 51, block, 0);
		this.setBlock(world, i + 0, j + 4, k + 52, block, 0);
		this.setBlock(world, i + 0, j + 4, k + 53, block, 0);
		this.setBlock(world, i + 0, j + 4, k + 54, block, 0);
		this.setBlock(world, i + 0, j + 4, k + 55, block, 0);
		this.setBlock(world, i + 0, j + 4, k + 56, block, 0);
		this.setBlock(world, i + 0, j + 4, k + 57, block, 0);
		this.setBlock(world, i + 0, j + 4, k + 58, block, 0);
		this.setBlock(world, i + 0, j + 4, k + 59, block, 0);
		this.setBlock(world, i + 0, j + 5, k + 43, block, 0);
		this.setBlock(world, i + 0, j + 5, k + 44, block, 0);
		this.setBlock(world, i + 0, j + 5, k + 45, block, 0);
		this.setBlock(world, i + 0, j + 5, k + 46, block, 0);
		this.setBlock(world, i + 0, j + 5, k + 47, block, 0);
		this.setBlock(world, i + 0, j + 5, k + 48, block, 0);
		this.setBlock(world, i + 0, j + 5, k + 49, block, 0);
		this.setBlock(world, i + 0, j + 5, k + 50, block, 0);
		this.setBlock(world, i + 0, j + 5, k + 51, block, 0);
		this.setBlock(world, i + 0, j + 5, k + 52, block, 0);
		this.setBlock(world, i + 0, j + 5, k + 53, block, 0);
		this.setBlock(world, i + 0, j + 5, k + 54, block, 0);
		this.setBlock(world, i + 0, j + 5, k + 55, block, 0);
		this.setBlock(world, i + 0, j + 5, k + 56, block, 0);
		this.setBlock(world, i + 0, j + 5, k + 57, block, 0);
		this.setBlock(world, i + 0, j + 5, k + 58, block, 0);
		this.setBlock(world, i + 0, j + 5, k + 59, block, 0);
		this.setBlock(world, i + 0, j + 6, k + 43, block, 0);
		this.setBlock(world, i + 0, j + 6, k + 44, block, 0);
		this.setBlock(world, i + 0, j + 6, k + 45, block, 0);
		this.setBlock(world, i + 0, j + 6, k + 46, block, 0);
		this.setBlock(world, i + 0, j + 6, k + 47, block, 0);
		this.setBlock(world, i + 0, j + 6, k + 48, block, 0);
		this.setBlock(world, i + 0, j + 6, k + 49, block, 0);
		this.setBlock(world, i + 0, j + 6, k + 50, block, 0);
		this.setBlock(world, i + 0, j + 6, k + 51, block, 0);
		this.setBlock(world, i + 0, j + 6, k + 52, block, 0);
		this.setBlock(world, i + 0, j + 6, k + 53, block, 0);
		this.setBlock(world, i + 0, j + 6, k + 54, block, 0);
		this.setBlock(world, i + 0, j + 6, k + 55, block, 0);
		this.setBlock(world, i + 0, j + 6, k + 56, block, 0);
		this.setBlock(world, i + 0, j + 6, k + 57, block, 0);
		this.setBlock(world, i + 0, j + 6, k + 58, block, 0);
		this.setBlock(world, i + 0, j + 6, k + 59, block, 0);
		this.setBlock(world, i + 0, j + 7, k + 43, block, 0);
		this.setBlock(world, i + 0, j + 7, k + 44, block, 0);
		this.setBlock(world, i + 0, j + 7, k + 45, block, 0);
		this.setBlock(world, i + 0, j + 7, k + 46, block, 0);
		this.setBlock(world, i + 0, j + 7, k + 47, block, 0);
		this.setBlock(world, i + 0, j + 7, k + 48, block, 0);
		this.setBlock(world, i + 0, j + 7, k + 49, block, 0);
		this.setBlock(world, i + 0, j + 7, k + 50, block, 0);
		this.setBlock(world, i + 0, j + 7, k + 51, block, 0);
		this.setBlock(world, i + 0, j + 7, k + 52, block, 0);
		this.setBlock(world, i + 0, j + 7, k + 53, block, 0);
		this.setBlock(world, i + 0, j + 7, k + 54, block, 0);
		this.setBlock(world, i + 0, j + 7, k + 55, block, 0);
		this.setBlock(world, i + 0, j + 7, k + 56, block, 0);
		this.setBlock(world, i + 0, j + 7, k + 57, block, 0);
		this.setBlock(world, i + 0, j + 7, k + 58, block, 0);
		this.setBlock(world, i + 0, j + 7, k + 59, block, 0);
		this.setBlock(world, i + 0, j + 8, k + 43, block, 0);
		this.setBlock(world, i + 0, j + 8, k + 44, block, 0);
		this.setBlock(world, i + 0, j + 8, k + 45, block, 0);
		this.setBlock(world, i + 0, j + 8, k + 46, block, 0);
		this.setBlock(world, i + 0, j + 8, k + 47, block, 0);
		this.setBlock(world, i + 0, j + 8, k + 48, block, 0);
		this.setBlock(world, i + 0, j + 8, k + 49, block, 0);
		this.setBlock(world, i + 0, j + 8, k + 50, block, 0);
		this.setBlock(world, i + 0, j + 8, k + 51, block, 0);
		this.setBlock(world, i + 0, j + 8, k + 52, block, 0);
		this.setBlock(world, i + 0, j + 8, k + 53, block, 0);
		this.setBlock(world, i + 0, j + 8, k + 54, block, 0);
		this.setBlock(world, i + 0, j + 8, k + 55, block, 0);
		this.setBlock(world, i + 0, j + 8, k + 56, block, 0);
		this.setBlock(world, i + 0, j + 8, k + 57, block, 0);
		this.setBlock(world, i + 0, j + 8, k + 58, block, 0);
		this.setBlock(world, i + 0, j + 8, k + 59, block, 0);
		this.setBlock(world, i + 0, j + 9, k + 43, slabBlock, 0);
		this.setBlock(world, i + 0, j + 9, k + 44, block, 0);
		this.setBlock(world, i + 0, j + 9, k + 45, block, 0);
		this.setBlock(world, i + 0, j + 9, k + 46, block, 0);
		this.setBlock(world, i + 0, j + 9, k + 47, block, 0);
		this.setBlock(world, i + 0, j + 9, k + 48, block, 0);
		this.setBlock(world, i + 0, j + 9, k + 49, block, 0);
		this.setBlock(world, i + 0, j + 9, k + 50, block, 0);
		this.setBlock(world, i + 0, j + 9, k + 51, block, 0);
		this.setBlock(world, i + 0, j + 9, k + 52, block, 0);
		this.setBlock(world, i + 0, j + 9, k + 53, block, 0);
		this.setBlock(world, i + 0, j + 9, k + 54, block, 0);
		this.setBlock(world, i + 0, j + 9, k + 55, block, 0);
		this.setBlock(world, i + 0, j + 9, k + 56, block, 0);
		this.setBlock(world, i + 0, j + 9, k + 57, block, 0);
		this.setBlock(world, i + 0, j + 9, k + 58, block, 0);
		this.setBlock(world, i + 0, j + 9, k + 59, slabBlock, 0);
		this.setBlock(world, i + 1, j + 0, k + 44, block, 0);
		this.setBlock(world, i + 1, j + 0, k + 45, block, 0);
		this.setBlock(world, i + 1, j + 0, k + 46, block, 0);
		this.setBlock(world, i + 1, j + 0, k + 47, block, 0);
		this.setBlock(world, i + 1, j + 0, k + 48, block, 0);
		this.setBlock(world, i + 1, j + 0, k + 49, block, 0);
		this.setBlock(world, i + 1, j + 0, k + 50, block, 0);
		this.setBlock(world, i + 1, j + 0, k + 51, block, 0);
		this.setBlock(world, i + 1, j + 0, k + 52, block, 0);
		this.setBlock(world, i + 1, j + 0, k + 53, block, 0);
		this.setBlock(world, i + 1, j + 0, k + 54, block, 0);
		this.setBlock(world, i + 1, j + 0, k + 55, block, 0);
		this.setBlock(world, i + 1, j + 0, k + 56, block, 0);
		this.setBlock(world, i + 1, j + 0, k + 57, block, 0);
		this.setBlock(world, i + 1, j + 0, k + 58, block, 0);
		this.setBlock(world, i + 1, j + 1, k + 43, block, 0);
		this.setBlock(world, i + 1, j + 1, k + 44, Blocks.air, 0);
		this.setBlock(world, i + 1, j + 1, k + 45, Blocks.air, 0);
		this.setBlock(world, i + 1, j + 1, k + 46, Blocks.air, 0);
		this.setBlock(world, i + 1, j + 1, k + 47, Blocks.air, 0);
		this.setBlock(world, i + 1, j + 1, k + 48, Blocks.air, 0);
		this.setBlock(world, i + 1, j + 1, k + 49, Blocks.air, 0);
		this.setBlock(world, i + 1, j + 1, k + 50, Blocks.air, 0);
		this.setBlock(world, i + 1, j + 1, k + 51, Blocks.air, 0);
		this.setBlock(world, i + 1, j + 1, k + 52, Blocks.air, 0);
		this.setBlock(world, i + 1, j + 1, k + 53, Blocks.air, 0);
		this.setBlock(world, i + 1, j + 1, k + 54, Blocks.air, 0);
		this.setBlock(world, i + 1, j + 1, k + 55, Blocks.air, 0);
		this.setBlock(world, i + 1, j + 1, k + 56, Blocks.air, 0);
		this.setBlock(world, i + 1, j + 1, k + 57, block, 0);
		this.setBlock(world, i + 1, j + 1, k + 58, block, 0);
		this.setBlock(world, i + 1, j + 1, k + 59, block, 0);
		this.setBlock(world, i + 1, j + 2, k + 43, block, 0);
		this.setBlock(world, i + 1, j + 2, k + 57, block, 0);
		this.setBlock(world, i + 1, j + 2, k + 58, block, 0);
		this.setBlock(world, i + 1, j + 2, k + 59, block, 0);
		this.setBlock(world, i + 1, j + 3, k + 43, block, 0);
		this.setBlock(world, i + 1, j + 3, k + 57, block, 0);
		this.setBlock(world, i + 1, j + 3, k + 58, block, 0);
		this.setBlock(world, i + 1, j + 3, k + 59, block, 0);
		this.setBlock(world, i + 1, j + 4, k + 43, block, 0);
		this.setBlock(world, i + 1, j + 4, k + 44, Blocks.iron_bars, 0);
		this.setBlock(world, i + 1, j + 4, k + 56, Blocks.iron_bars, 0);
		this.setBlock(world, i + 1, j + 4, k + 57, block, 0);
		this.setBlock(world, i + 1, j + 4, k + 58, block, 0);
		this.setBlock(world, i + 1, j + 4, k + 59, block, 0);
		this.setBlock(world, i + 1, j + 5, k + 43, block, 0);
		this.setBlock(world, i + 1, j + 5, k + 44, block, 0);
		this.setBlock(world, i + 1, j + 5, k + 45, block, 0);
		this.setBlock(world, i + 1, j + 5, k + 46, block, 0);
		this.setBlock(world, i + 1, j + 5, k + 47, block, 0);
		this.setBlock(world, i + 1, j + 5, k + 48, block, 0);
		this.setBlock(world, i + 1, j + 5, k + 49, block, 0);
		this.setBlock(world, i + 1, j + 5, k + 50, block, 0);
		this.setBlock(world, i + 1, j + 5, k + 51, block, 0);
		this.setBlock(world, i + 1, j + 5, k + 52, block, 0);
		this.setBlock(world, i + 1, j + 5, k + 53, block, 0);
		this.setBlock(world, i + 1, j + 5, k + 54, block, 0);
		this.setBlock(world, i + 1, j + 5, k + 55, block, 0);
		this.setBlock(world, i + 1, j + 5, k + 56, block, 0);
		this.setBlock(world, i + 1, j + 5, k + 57, block, 0);
		this.setBlock(world, i + 1, j + 5, k + 58, block, 0);
		this.setBlock(world, i + 1, j + 5, k + 59, block, 0);
		this.setBlock(world, i + 1, j + 6, k + 43, block, 0);
		this.setBlock(world, i + 1, j + 6, k + 44, block, 0);
		this.setBlock(world, i + 1, j + 6, k + 45, block, 0);
		this.setBlock(world, i + 1, j + 6, k + 46, block, 0);
		this.setBlock(world, i + 1, j + 6, k + 47, block, 0);
		this.setBlock(world, i + 1, j + 6, k + 48, block, 0);
		this.setBlock(world, i + 1, j + 6, k + 49, block, 0);
		this.setBlock(world, i + 1, j + 6, k + 50, block, 0);
		this.setBlock(world, i + 1, j + 6, k + 51, block, 0);
		this.setBlock(world, i + 1, j + 6, k + 52, block, 0);
		this.setBlock(world, i + 1, j + 6, k + 53, block, 0);
		this.setBlock(world, i + 1, j + 6, k + 54, block, 0);
		this.setBlock(world, i + 1, j + 6, k + 55, block, 0);
		this.setBlock(world, i + 1, j + 6, k + 56, block, 0);
		this.setBlock(world, i + 1, j + 6, k + 57, block, 0);
		this.setBlock(world, i + 1, j + 6, k + 58, block, 0);
		this.setBlock(world, i + 1, j + 6, k + 59, block, 0);
		this.setBlock(world, i + 1, j + 7, k + 43, block, 0);
		this.setBlock(world, i + 1, j + 7, k + 44, block, 0);
		this.setBlock(world, i + 1, j + 7, k + 45, block, 0);
		this.setBlock(world, i + 1, j + 7, k + 46, block, 0);
		this.setBlock(world, i + 1, j + 7, k + 47, block, 0);
		this.setBlock(world, i + 1, j + 7, k + 48, block, 0);
		this.setBlock(world, i + 1, j + 7, k + 49, block, 0);
		this.setBlock(world, i + 1, j + 7, k + 50, block, 0);
		this.setBlock(world, i + 1, j + 7, k + 51, block, 0);
		this.setBlock(world, i + 1, j + 7, k + 52, block, 0);
		this.setBlock(world, i + 1, j + 7, k + 53, block, 0);
		this.setBlock(world, i + 1, j + 7, k + 54, block, 0);
		this.setBlock(world, i + 1, j + 7, k + 55, block, 0);
		this.setBlock(world, i + 1, j + 7, k + 56, block, 0);
		this.setBlock(world, i + 1, j + 7, k + 57, block, 0);
		this.setBlock(world, i + 1, j + 7, k + 58, block, 0);
		this.setBlock(world, i + 1, j + 7, k + 59, block, 0);
		this.setBlock(world, i + 1, j + 8, k + 43, block, 0);
		this.setBlock(world, i + 1, j + 8, k + 44, block, 0);
		this.setBlock(world, i + 1, j + 8, k + 45, block, 0);
		this.setBlock(world, i + 1, j + 8, k + 46, block, 0);
		this.setBlock(world, i + 1, j + 8, k + 47, block, 0);
		this.setBlock(world, i + 1, j + 8, k + 48, block, 0);
		this.setBlock(world, i + 1, j + 8, k + 49, block, 0);
		this.setBlock(world, i + 1, j + 8, k + 50, block, 0);
		this.setBlock(world, i + 1, j + 8, k + 51, block, 0);
		this.setBlock(world, i + 1, j + 8, k + 52, block, 0);
		this.setBlock(world, i + 1, j + 8, k + 53, block, 0);
		this.setBlock(world, i + 1, j + 8, k + 54, block, 0);
		this.setBlock(world, i + 1, j + 8, k + 55, block, 0);
		this.setBlock(world, i + 1, j + 8, k + 56, block, 0);
		this.setBlock(world, i + 1, j + 8, k + 57, block, 0);
		this.setBlock(world, i + 1, j + 8, k + 58, block, 0);
		this.setBlock(world, i + 1, j + 8, k + 59, block, 0);
		this.setBlock(world, i + 1, j + 9, k + 43, block, 0);
		this.setBlock(world, i + 1, j + 9, k + 44, block, 0);
		this.setBlock(world, i + 1, j + 9, k + 45, block, 0);
		this.setBlock(world, i + 1, j + 9, k + 46, block, 0);
		this.setBlock(world, i + 1, j + 9, k + 47, block, 0);
		this.setBlock(world, i + 1, j + 9, k + 48, block, 0);
		this.setBlock(world, i + 1, j + 9, k + 49, block, 0);
		this.setBlock(world, i + 1, j + 9, k + 50, block, 0);
		this.setBlock(world, i + 1, j + 9, k + 51, block, 0);
		this.setBlock(world, i + 1, j + 9, k + 52, block, 0);
		this.setBlock(world, i + 1, j + 9, k + 53, block, 0);
		this.setBlock(world, i + 1, j + 9, k + 54, block, 0);
		this.setBlock(world, i + 1, j + 9, k + 55, block, 0);
		this.setBlock(world, i + 1, j + 9, k + 56, block, 0);
		this.setBlock(world, i + 1, j + 9, k + 57, block, 0);
		this.setBlock(world, i + 1, j + 9, k + 58, block, 0);
		this.setBlock(world, i + 1, j + 9, k + 59, block, 0);
		this.setBlock(world, i + 1, j + 10, k + 44, slabBlock, 0);
		this.setBlock(world, i + 1, j + 10, k + 45, block, 0);
		this.setBlock(world, i + 1, j + 10, k + 46, block, 0);
		this.setBlock(world, i + 1, j + 10, k + 47, block, 0);
		this.setBlock(world, i + 1, j + 10, k + 48, block, 0);
		this.setBlock(world, i + 1, j + 10, k + 49, block, 0);
		this.setBlock(world, i + 1, j + 10, k + 50, block, 0);
		this.setBlock(world, i + 1, j + 10, k + 51, block, 0);
		this.setBlock(world, i + 1, j + 10, k + 52, block, 0);
		this.setBlock(world, i + 1, j + 10, k + 53, block, 0);
		this.setBlock(world, i + 1, j + 10, k + 54, block, 0);
		this.setBlock(world, i + 1, j + 10, k + 55, block, 0);
		this.setBlock(world, i + 1, j + 10, k + 56, block, 0);
		this.setBlock(world, i + 1, j + 10, k + 57, block, 0);
		this.setBlock(world, i + 1, j + 10, k + 58, slabBlock, 0);
		this.setBlock(world, i + 2, j + 0, k + 44, block, 0);
		this.setBlock(world, i + 2, j + 0, k + 45, block, 0);
		this.setBlock(world, i + 2, j + 0, k + 46, block, 0);
		this.setBlock(world, i + 2, j + 0, k + 47, block, 0);
		this.setBlock(world, i + 2, j + 0, k + 48, block, 0);
		this.setBlock(world, i + 2, j + 0, k + 49, block, 0);
		this.setBlock(world, i + 2, j + 0, k + 50, block, 0);
		this.setBlock(world, i + 2, j + 0, k + 51, block, 0);
		this.setBlock(world, i + 2, j + 0, k + 52, block, 0);
		this.setBlock(world, i + 2, j + 0, k + 53, block, 0);
		this.setBlock(world, i + 2, j + 0, k + 54, block, 0);
		this.setBlock(world, i + 2, j + 0, k + 55, block, 0);
		this.setBlock(world, i + 2, j + 0, k + 56, block, 0);
		this.setBlock(world, i + 2, j + 0, k + 57, block, 0);
		this.setBlock(world, i + 2, j + 0, k + 58, block, 0);
		this.setBlock(world, i + 2, j + 1, k + 16, slabBlock, 8);
		this.setBlock(world, i + 2, j + 1, k + 17, block, 0);
		this.setBlock(world, i + 2, j + 1, k + 18, block, 0);
		this.setBlock(world, i + 2, j + 1, k + 19, block, 0);
		this.setBlock(world, i + 2, j + 1, k + 20, block, 0);
		this.setBlock(world, i + 2, j + 1, k + 21, block, 0);
		this.setBlock(world, i + 2, j + 1, k + 22, block, 0);
		this.setBlock(world, i + 2, j + 1, k + 23, block, 0);
		this.setBlock(world, i + 2, j + 1, k + 24, block, 0);
		this.setBlock(world, i + 2, j + 1, k + 25, block, 0);
		this.setBlock(world, i + 2, j + 1, k + 26, slabBlock, 8);
		this.setBlock(world, i + 2, j + 1, k + 43, block, 0);
		this.setBlock(world, i + 2, j + 1, k + 44, Blocks.air, 0);
		this.setBlock(world, i + 2, j + 1, k + 45, Blocks.air, 0);
		this.setBlock(world, i + 2, j + 1, k + 46, Blocks.air, 0);
		this.setBlock(world, i + 2, j + 1, k + 47, Blocks.air, 0);
		this.setBlock(world, i + 2, j + 1, k + 48, Blocks.air, 0);
		this.setBlock(world, i + 2, j + 1, k + 49, Blocks.air, 0);
		this.setBlock(world, i + 2, j + 1, k + 50, Blocks.air, 0);
		this.setBlock(world, i + 2, j + 1, k + 51, Blocks.air, 0);
		this.setBlock(world, i + 2, j + 1, k + 52, Blocks.air, 0);
		this.setBlock(world, i + 2, j + 1, k + 53, Blocks.air, 0);
		this.setBlock(world, i + 2, j + 1, k + 54, Blocks.air, 0);
		this.setBlock(world, i + 2, j + 1, k + 55, Blocks.air, 0);
		this.setBlock(world, i + 2, j + 1, k + 56, Blocks.air, 0);
		this.setBlock(world, i + 2, j + 1, k + 57, Blocks.air, 0);
		this.setBlock(world, i + 2, j + 1, k + 58, block, 0);
		this.setBlock(world, i + 2, j + 1, k + 59, block, 0);
		this.setBlock(world, i + 2, j + 2, k + 16, block, 0);
		this.setBlock(world, i + 2, j + 2, k + 17, block, 0);
		this.setBlock(world, i + 2, j + 2, k + 18, block, 0);
		this.setBlock(world, i + 2, j + 2, k + 19, block, 0);
		this.setBlock(world, i + 2, j + 2, k + 20, block, 0);
		this.setBlock(world, i + 2, j + 2, k + 21, block, 0);
		this.setBlock(world, i + 2, j + 2, k + 22, block, 0);
		this.setBlock(world, i + 2, j + 2, k + 23, block, 0);
		this.setBlock(world, i + 2, j + 2, k + 24, block, 0);
		this.setBlock(world, i + 2, j + 2, k + 25, block, 0);
		this.setBlock(world, i + 2, j + 2, k + 26, block, 0);
		this.setBlock(world, i + 2, j + 2, k + 43, block, 0);
		this.setBlock(world, i + 2, j + 2, k + 58, block, 0);
		this.setBlock(world, i + 2, j + 2, k + 59, block, 0);
		this.setBlock(world, i + 2, j + 3, k + 16, block, 0);
		this.setBlock(world, i + 2, j + 3, k + 17, block, 0);
		this.setBlock(world, i + 2, j + 3, k + 18, block, 0);
		this.setBlock(world, i + 2, j + 3, k + 19, block, 0);
		this.setBlock(world, i + 2, j + 3, k + 20, block, 0);
		this.setBlock(world, i + 2, j + 3, k + 21, block, 0);
		this.setBlock(world, i + 2, j + 3, k + 22, block, 0);
		this.setBlock(world, i + 2, j + 3, k + 23, block, 0);
		this.setBlock(world, i + 2, j + 3, k + 24, block, 0);
		this.setBlock(world, i + 2, j + 3, k + 25, block, 0);
		this.setBlock(world, i + 2, j + 3, k + 26, block, 0);
		this.setBlock(world, i + 2, j + 3, k + 43, block, 0);
		this.setBlock(world, i + 2, j + 3, k + 58, block, 0);
		this.setBlock(world, i + 2, j + 3, k + 59, block, 0);
		this.setBlock(world, i + 2, j + 4, k + 16, block, 0);
		this.setBlock(world, i + 2, j + 4, k + 17, block, 0);
		this.setBlock(world, i + 2, j + 4, k + 18, block, 0);
		this.setBlock(world, i + 2, j + 4, k + 19, block, 0);
		this.setBlock(world, i + 2, j + 4, k + 20, block, 0);
		this.setBlock(world, i + 2, j + 4, k + 21, block, 0);
		this.setBlock(world, i + 2, j + 4, k + 22, block, 0);
		this.setBlock(world, i + 2, j + 4, k + 23, block, 0);
		this.setBlock(world, i + 2, j + 4, k + 24, block, 0);
		this.setBlock(world, i + 2, j + 4, k + 25, block, 0);
		this.setBlock(world, i + 2, j + 4, k + 26, block, 0);
		this.setBlock(world, i + 2, j + 4, k + 43, block, 0);
		this.setBlock(world, i + 2, j + 4, k + 57, Blocks.iron_bars, 0);
		this.setBlock(world, i + 2, j + 4, k + 58, block, 0);
		this.setBlock(world, i + 2, j + 4, k + 59, block, 0);
		this.setBlock(world, i + 2, j + 5, k + 16, block, 0);
		this.setBlock(world, i + 2, j + 5, k + 17, block, 0);
		this.setBlock(world, i + 2, j + 5, k + 18, block, 0);
		this.setBlock(world, i + 2, j + 5, k + 19, block, 0);
		this.setBlock(world, i + 2, j + 5, k + 20, block, 0);
		this.setBlock(world, i + 2, j + 5, k + 21, block, 0);
		this.setBlock(world, i + 2, j + 5, k + 22, block, 0);
		this.setBlock(world, i + 2, j + 5, k + 23, block, 0);
		this.setBlock(world, i + 2, j + 5, k + 24, block, 0);
		this.setBlock(world, i + 2, j + 5, k + 25, block, 0);
		this.setBlock(world, i + 2, j + 5, k + 26, block, 0);
		this.setBlock(world, i + 2, j + 5, k + 43, block, 0);
		this.setBlock(world, i + 2, j + 5, k + 44, block, 0);
		this.setBlock(world, i + 2, j + 5, k + 45, block, 0);
		this.setBlock(world, i + 2, j + 5, k + 46, block, 0);
		this.setBlock(world, i + 2, j + 5, k + 47, block, 0);
		this.setBlock(world, i + 2, j + 5, k + 48, block, 0);
		this.setBlock(world, i + 2, j + 5, k + 49, block, 0);
		this.setBlock(world, i + 2, j + 5, k + 50, block, 0);
		this.setBlock(world, i + 2, j + 5, k + 51, block, 0);
		this.setBlock(world, i + 2, j + 5, k + 52, block, 0);
		this.setBlock(world, i + 2, j + 5, k + 53, block, 0);
		this.setBlock(world, i + 2, j + 5, k + 54, block, 0);
		this.setBlock(world, i + 2, j + 5, k + 55, block, 0);
		this.setBlock(world, i + 2, j + 5, k + 56, block, 0);
		this.setBlock(world, i + 2, j + 5, k + 57, block, 0);
		this.setBlock(world, i + 2, j + 5, k + 58, block, 0);
		this.setBlock(world, i + 2, j + 5, k + 59, block, 0);
		this.setBlock(world, i + 2, j + 6, k + 16, block, 0);
		this.setBlock(world, i + 2, j + 6, k + 17, block, 0);
		this.setBlock(world, i + 2, j + 6, k + 18, block, 0);
		this.setBlock(world, i + 2, j + 6, k + 19, block, 0);
		this.setBlock(world, i + 2, j + 6, k + 20, block, 0);
		this.setBlock(world, i + 2, j + 6, k + 21, block, 0);
		this.setBlock(world, i + 2, j + 6, k + 22, block, 0);
		this.setBlock(world, i + 2, j + 6, k + 23, block, 0);
		this.setBlock(world, i + 2, j + 6, k + 24, block, 0);
		this.setBlock(world, i + 2, j + 6, k + 25, block, 0);
		this.setBlock(world, i + 2, j + 6, k + 26, block, 0);
		this.setBlock(world, i + 2, j + 6, k + 43, block, 0);
		this.setBlock(world, i + 2, j + 6, k + 44, block, 0);
		this.setBlock(world, i + 2, j + 6, k + 45, block, 0);
		this.setBlock(world, i + 2, j + 6, k + 46, block, 0);
		this.setBlock(world, i + 2, j + 6, k + 47, block, 0);
		this.setBlock(world, i + 2, j + 6, k + 48, block, 0);
		this.setBlock(world, i + 2, j + 6, k + 49, block, 0);
		this.setBlock(world, i + 2, j + 6, k + 50, block, 0);
		this.setBlock(world, i + 2, j + 6, k + 51, block, 0);
		this.setBlock(world, i + 2, j + 6, k + 52, block, 0);
		this.setBlock(world, i + 2, j + 6, k + 53, block, 0);
		this.setBlock(world, i + 2, j + 6, k + 54, block, 0);
		this.setBlock(world, i + 2, j + 6, k + 55, block, 0);
		this.setBlock(world, i + 2, j + 6, k + 56, block, 0);
		this.setBlock(world, i + 2, j + 6, k + 57, block, 0);
		this.setBlock(world, i + 2, j + 6, k + 58, block, 0);
		this.setBlock(world, i + 2, j + 6, k + 59, block, 0);
		this.setBlock(world, i + 2, j + 7, k + 16, block, 0);
		this.setBlock(world, i + 2, j + 7, k + 17, block, 0);
		this.setBlock(world, i + 2, j + 7, k + 18, block, 0);
		this.setBlock(world, i + 2, j + 7, k + 19, block, 0);
		this.setBlock(world, i + 2, j + 7, k + 20, block, 0);
		this.setBlock(world, i + 2, j + 7, k + 21, block, 0);
		this.setBlock(world, i + 2, j + 7, k + 22, block, 0);
		this.setBlock(world, i + 2, j + 7, k + 23, block, 0);
		this.setBlock(world, i + 2, j + 7, k + 24, block, 0);
		this.setBlock(world, i + 2, j + 7, k + 25, block, 0);
		this.setBlock(world, i + 2, j + 7, k + 26, block, 0);
		this.setBlock(world, i + 2, j + 7, k + 43, block, 0);
		this.setBlock(world, i + 2, j + 7, k + 44, block, 0);
		this.setBlock(world, i + 2, j + 7, k + 45, block, 0);
		this.setBlock(world, i + 2, j + 7, k + 46, block, 0);
		this.setBlock(world, i + 2, j + 7, k + 47, block, 0);
		this.setBlock(world, i + 2, j + 7, k + 48, block, 0);
		this.setBlock(world, i + 2, j + 7, k + 49, block, 0);
		this.setBlock(world, i + 2, j + 7, k + 50, block, 0);
		this.setBlock(world, i + 2, j + 7, k + 51, block, 0);
		this.setBlock(world, i + 2, j + 7, k + 52, block, 0);
		this.setBlock(world, i + 2, j + 7, k + 53, block, 0);
		this.setBlock(world, i + 2, j + 7, k + 54, block, 0);
		this.setBlock(world, i + 2, j + 7, k + 55, block, 0);
		this.setBlock(world, i + 2, j + 7, k + 56, block, 0);
		this.setBlock(world, i + 2, j + 7, k + 57, block, 0);
		this.setBlock(world, i + 2, j + 7, k + 58, block, 0);
		this.setBlock(world, i + 2, j + 7, k + 59, block, 0);
		this.setBlock(world, i + 2, j + 8, k + 16, block, 0);
		this.setBlock(world, i + 2, j + 8, k + 17, block, 0);
		this.setBlock(world, i + 2, j + 8, k + 18, block, 0);
		this.setBlock(world, i + 2, j + 8, k + 19, block, 0);
		this.setBlock(world, i + 2, j + 8, k + 20, block, 0);
		this.setBlock(world, i + 2, j + 8, k + 21, block, 0);
		this.setBlock(world, i + 2, j + 8, k + 22, block, 0);
		this.setBlock(world, i + 2, j + 8, k + 23, block, 0);
		this.setBlock(world, i + 2, j + 8, k + 24, block, 0);
		this.setBlock(world, i + 2, j + 8, k + 25, block, 0);
		this.setBlock(world, i + 2, j + 8, k + 26, block, 0);
		this.setBlock(world, i + 2, j + 8, k + 43, block, 0);
		this.setBlock(world, i + 2, j + 8, k + 44, block, 0);
		this.setBlock(world, i + 2, j + 8, k + 45, block, 0);
		this.setBlock(world, i + 2, j + 8, k + 46, block, 0);
		this.setBlock(world, i + 2, j + 8, k + 47, block, 0);
		this.setBlock(world, i + 2, j + 8, k + 48, block, 0);
		this.setBlock(world, i + 2, j + 8, k + 49, block, 0);
		this.setBlock(world, i + 2, j + 8, k + 50, block, 0);
		this.setBlock(world, i + 2, j + 8, k + 51, block, 0);
		this.setBlock(world, i + 2, j + 8, k + 52, block, 0);
		this.setBlock(world, i + 2, j + 8, k + 53, block, 0);
		this.setBlock(world, i + 2, j + 8, k + 54, block, 0);
		this.setBlock(world, i + 2, j + 8, k + 55, block, 0);
		this.setBlock(world, i + 2, j + 8, k + 56, block, 0);
		this.setBlock(world, i + 2, j + 8, k + 57, block, 0);
		this.setBlock(world, i + 2, j + 8, k + 58, block, 0);
		this.setBlock(world, i + 2, j + 8, k + 59, block, 0);
		this.setBlock(world, i + 2, j + 9, k + 16, slabBlock, 0);
		this.setBlock(world, i + 2, j + 9, k + 17, block, 0);
		this.setBlock(world, i + 2, j + 9, k + 18, block, 0);
		this.setBlock(world, i + 2, j + 9, k + 19, block, 0);
		this.setBlock(world, i + 2, j + 9, k + 20, block, 0);
		this.setBlock(world, i + 2, j + 9, k + 21, block, 0);
		this.setBlock(world, i + 2, j + 9, k + 22, block, 0);
		this.setBlock(world, i + 2, j + 9, k + 23, block, 0);
		this.setBlock(world, i + 2, j + 9, k + 24, block, 0);
		this.setBlock(world, i + 2, j + 9, k + 25, block, 0);
		this.setBlock(world, i + 2, j + 9, k + 26, slabBlock, 0);
		this.setBlock(world, i + 2, j + 9, k + 43, block, 0);
		this.setBlock(world, i + 2, j + 9, k + 44, block, 0);
		this.setBlock(world, i + 2, j + 9, k + 45, block, 0);
		this.setBlock(world, i + 2, j + 9, k + 46, block, 0);
		this.setBlock(world, i + 2, j + 9, k + 47, block, 0);
		this.setBlock(world, i + 2, j + 9, k + 48, block, 0);
		this.setBlock(world, i + 2, j + 9, k + 49, block, 0);
		this.setBlock(world, i + 2, j + 9, k + 50, block, 0);
		this.setBlock(world, i + 2, j + 9, k + 51, block, 0);
		this.setBlock(world, i + 2, j + 9, k + 52, block, 0);
		this.setBlock(world, i + 2, j + 9, k + 53, block, 0);
		this.setBlock(world, i + 2, j + 9, k + 54, block, 0);
		this.setBlock(world, i + 2, j + 9, k + 55, block, 0);
		this.setBlock(world, i + 2, j + 9, k + 56, block, 0);
		this.setBlock(world, i + 2, j + 9, k + 57, block, 0);
		this.setBlock(world, i + 2, j + 9, k + 58, block, 0);
		this.setBlock(world, i + 2, j + 9, k + 59, block, 0);
		this.setBlock(world, i + 2, j + 10, k + 44, block, 0);
		this.setBlock(world, i + 2, j + 10, k + 45, block, 0);
		this.setBlock(world, i + 2, j + 10, k + 46, block, 0);
		this.setBlock(world, i + 2, j + 10, k + 47, block, 0);
		this.setBlock(world, i + 2, j + 10, k + 48, block, 0);
		this.setBlock(world, i + 2, j + 10, k + 49, block, 0);
		this.setBlock(world, i + 2, j + 10, k + 50, block, 0);
		this.setBlock(world, i + 2, j + 10, k + 51, block, 0);
		this.setBlock(world, i + 2, j + 10, k + 52, block, 0);
		this.setBlock(world, i + 2, j + 10, k + 53, block, 0);
		this.setBlock(world, i + 2, j + 10, k + 54, block, 0);
		this.setBlock(world, i + 2, j + 10, k + 55, block, 0);
		this.setBlock(world, i + 2, j + 10, k + 56, block, 0);
		this.setBlock(world, i + 2, j + 10, k + 57, block, 0);
		this.setBlock(world, i + 2, j + 10, k + 58, block, 0);
		this.setBlock(world, i + 3, j + 0, k + 17, block, 0);
		this.setBlock(world, i + 3, j + 0, k + 18, block, 0);
		this.setBlock(world, i + 3, j + 0, k + 19, block, 0);
		this.setBlock(world, i + 3, j + 0, k + 20, block, 0);
		this.setBlock(world, i + 3, j + 0, k + 21, block, 0);
		this.setBlock(world, i + 3, j + 0, k + 22, block, 0);
		this.setBlock(world, i + 3, j + 0, k + 23, block, 0);
		this.setBlock(world, i + 3, j + 0, k + 24, block, 0);
		this.setBlock(world, i + 3, j + 0, k + 25, block, 0);
		this.setBlock(world, i + 3, j + 0, k + 44, block, 0);
		this.setBlock(world, i + 3, j + 0, k + 45, block, 0);
		this.setBlock(world, i + 3, j + 0, k + 46, block, 0);
		this.setBlock(world, i + 3, j + 0, k + 47, block, 0);
		this.setBlock(world, i + 3, j + 0, k + 48, block, 0);
		this.setBlock(world, i + 3, j + 0, k + 49, block, 0);
		this.setBlock(world, i + 3, j + 0, k + 50, block, 0);
		this.setBlock(world, i + 3, j + 0, k + 51, block, 0);
		this.setBlock(world, i + 3, j + 0, k + 52, block, 0);
		this.setBlock(world, i + 3, j + 0, k + 53, block, 0);
		this.setBlock(world, i + 3, j + 0, k + 54, block, 0);
		this.setBlock(world, i + 3, j + 0, k + 55, block, 0);
		this.setBlock(world, i + 3, j + 0, k + 56, block, 0);
		this.setBlock(world, i + 3, j + 0, k + 57, block, 0);
		this.setBlock(world, i + 3, j + 0, k + 58, block, 0);
		this.setBlock(world, i + 3, j + 1, k + 16, block, 0);
		this.setBlock(world, i + 3, j + 1, k + 17, block, 0);
		this.setBlock(world, i + 3, j + 1, k + 18, Blocks.air, 0);
		this.setBlock(world, i + 3, j + 1, k + 19, Blocks.air, 0);
		this.setBlock(world, i + 3, j + 1, k + 20, Blocks.air, 0);
		this.setBlock(world, i + 3, j + 1, k + 21, Blocks.air, 0);
		this.setBlock(world, i + 3, j + 1, k + 22, Blocks.air, 0);
		this.setBlock(world, i + 3, j + 1, k + 23, Blocks.air, 0);
		this.setBlock(world, i + 3, j + 1, k + 24, Blocks.air, 0);
		this.setBlock(world, i + 3, j + 1, k + 25, Blocks.air, 0);
		this.setBlock(world, i + 3, j + 1, k + 26, block, 0);
		this.setBlock(world, i + 3, j + 1, k + 43, block, 0);
		this.setBlock(world, i + 3, j + 1, k + 44, Blocks.air, 0);
		this.setBlock(world, i + 3, j + 1, k + 45, block, 0);
		this.setBlock(world, i + 3, j + 1, k + 46, block, 0);
		this.setBlock(world, i + 3, j + 1, k + 47, block, 0);
		this.setBlock(world, i + 3, j + 1, k + 48, block, 0);
		this.setBlock(world, i + 3, j + 1, k + 49, block, 0);
		this.setBlock(world, i + 3, j + 1, k + 50, block, 0);
		this.setBlock(world, i + 3, j + 1, k + 51, block, 0);
		this.setBlock(world, i + 3, j + 1, k + 52, Blocks.air, 0);
		this.setBlock(world, i + 3, j + 1, k + 53, Blocks.air, 0);
		this.setBlock(world, i + 3, j + 1, k + 54, Blocks.air, 0);
		this.setBlock(world, i + 3, j + 1, k + 55, Blocks.air, 0);
		this.setBlock(world, i + 3, j + 1, k + 56, Blocks.air, 0);
		this.setBlock(world, i + 3, j + 1, k + 57, Blocks.air, 0);
		this.setBlock(world, i + 3, j + 1, k + 58, Blocks.air, 0);
		this.setBlock(world, i + 3, j + 1, k + 59, block, 0);
		this.setBlock(world, i + 3, j + 2, k + 16, block, 0);
		this.setBlock(world, i + 3, j + 2, k + 17, block, 0);
		this.setBlock(world, i + 3, j + 2, k + 26, block, 0);
		this.setBlock(world, i + 3, j + 2, k + 43, block, 0);
		this.setBlock(world, i + 3, j + 2, k + 45, block, 0);
		this.setBlock(world, i + 3, j + 2, k + 46, block, 0);
		this.setBlock(world, i + 3, j + 2, k + 47, block, 0);
		this.setBlock(world, i + 3, j + 2, k + 48, block, 0);
		this.setBlock(world, i + 3, j + 2, k + 49, block, 0);
		this.setBlock(world, i + 3, j + 2, k + 50, block, 0);
		this.setBlock(world, i + 3, j + 2, k + 51, block, 0);
		this.setBlock(world, i + 3, j + 2, k + 59, block, 0);
		this.setBlock(world, i + 3, j + 3, k + 16, block, 0);
		this.setBlock(world, i + 3, j + 3, k + 17, block, 0);
		this.setBlock(world, i + 3, j + 3, k + 26, block, 0);
		this.setBlock(world, i + 3, j + 3, k + 43, block, 0);
		this.setBlock(world, i + 3, j + 3, k + 45, block, 0);
		this.setBlock(world, i + 3, j + 3, k + 46, block, 0);
		this.setBlock(world, i + 3, j + 3, k + 47, block, 0);
		this.setBlock(world, i + 3, j + 3, k + 48, block, 0);
		this.setBlock(world, i + 3, j + 3, k + 49, block, 0);
		this.setBlock(world, i + 3, j + 3, k + 50, block, 0);
		this.setBlock(world, i + 3, j + 3, k + 51, block, 0);
		this.setBlock(world, i + 3, j + 3, k + 59, block, 0);
		this.setBlock(world, i + 3, j + 4, k + 16, block, 0);
		this.setBlock(world, i + 3, j + 4, k + 17, block, 0);
		this.setBlock(world, i + 3, j + 4, k + 26, block, 0);
		this.setBlock(world, i + 3, j + 4, k + 43, block, 0);
		this.setBlock(world, i + 3, j + 4, k + 44, slabBlock, 8);
		this.setBlock(world, i + 3, j + 4, k + 45, block, 0);
		this.setBlock(world, i + 3, j + 4, k + 46, block, 0);
		this.setBlock(world, i + 3, j + 4, k + 47, block, 0);
		this.setBlock(world, i + 3, j + 4, k + 48, block, 0);
		this.setBlock(world, i + 3, j + 4, k + 49, block, 0);
		this.setBlock(world, i + 3, j + 4, k + 50, block, 0);
		this.setBlock(world, i + 3, j + 4, k + 51, block, 0);
		this.setBlock(world, i + 3, j + 4, k + 58, Blocks.iron_bars, 0);
		this.setBlock(world, i + 3, j + 4, k + 59, block, 0);
		this.setBlock(world, i + 3, j + 5, k + 16, block, 0);
		this.setBlock(world, i + 3, j + 5, k + 17, block, 0);
		this.setBlock(world, i + 3, j + 5, k + 18, block, 0);
		this.setBlock(world, i + 3, j + 5, k + 19, block, 0);
		this.setBlock(world, i + 3, j + 5, k + 20, block, 0);
		this.setBlock(world, i + 3, j + 5, k + 21, block, 0);
		this.setBlock(world, i + 3, j + 5, k + 22, block, 0);
		this.setBlock(world, i + 3, j + 5, k + 23, block, 0);
		this.setBlock(world, i + 3, j + 5, k + 24, block, 0);
		this.setBlock(world, i + 3, j + 5, k + 25, block, 0);
		this.setBlock(world, i + 3, j + 5, k + 26, block, 0);
		this.setBlock(world, i + 3, j + 5, k + 43, block, 0);
		this.setBlock(world, i + 3, j + 5, k + 44, block, 0);
		this.setBlock(world, i + 3, j + 5, k + 45, block, 0);
		this.setBlock(world, i + 3, j + 5, k + 46, block, 0);
		this.setBlock(world, i + 3, j + 5, k + 47, block, 0);
		this.setBlock(world, i + 3, j + 5, k + 48, block, 0);
		this.setBlock(world, i + 3, j + 5, k + 49, block, 0);
		this.setBlock(world, i + 3, j + 5, k + 50, block, 0);
		this.setBlock(world, i + 3, j + 5, k + 51, block, 0);
		this.setBlock(world, i + 3, j + 5, k + 52, block, 0);
		this.setBlock(world, i + 3, j + 5, k + 53, block, 0);
		this.setBlock(world, i + 3, j + 5, k + 54, block, 0);
		this.setBlock(world, i + 3, j + 5, k + 55, block, 0);
		this.setBlock(world, i + 3, j + 5, k + 56, block, 0);
		this.setBlock(world, i + 3, j + 5, k + 57, block, 0);
		this.setBlock(world, i + 3, j + 5, k + 58, block, 0);
		this.setBlock(world, i + 3, j + 5, k + 59, block, 0);
		this.setBlock(world, i + 3, j + 6, k + 16, block, 0);
		this.setBlock(world, i + 3, j + 6, k + 17, block, 0);
		this.setBlock(world, i + 3, j + 6, k + 18, block, 0);
		this.setBlock(world, i + 3, j + 6, k + 19, block, 0);
		this.setBlock(world, i + 3, j + 6, k + 20, block, 0);
		this.setBlock(world, i + 3, j + 6, k + 21, block, 0);
		this.setBlock(world, i + 3, j + 6, k + 22, block, 0);
		this.setBlock(world, i + 3, j + 6, k + 23, block, 0);
		this.setBlock(world, i + 3, j + 6, k + 24, block, 0);
		this.setBlock(world, i + 3, j + 6, k + 25, block, 0);
		this.setBlock(world, i + 3, j + 6, k + 26, block, 0);
		this.setBlock(world, i + 3, j + 6, k + 43, block, 0);
		this.setBlock(world, i + 3, j + 6, k + 44, block, 0);
		this.setBlock(world, i + 3, j + 6, k + 45, block, 0);
		this.setBlock(world, i + 3, j + 6, k + 46, block, 0);
		this.setBlock(world, i + 3, j + 6, k + 47, block, 0);
		this.setBlock(world, i + 3, j + 6, k + 48, block, 0);
		this.setBlock(world, i + 3, j + 6, k + 49, block, 0);
		this.setBlock(world, i + 3, j + 6, k + 50, block, 0);
		this.setBlock(world, i + 3, j + 6, k + 51, block, 0);
		this.setBlock(world, i + 3, j + 6, k + 52, block, 0);
		this.setBlock(world, i + 3, j + 6, k + 53, block, 0);
		this.setBlock(world, i + 3, j + 6, k + 54, block, 0);
		this.setBlock(world, i + 3, j + 6, k + 55, block, 0);
		this.setBlock(world, i + 3, j + 6, k + 56, block, 0);
		this.setBlock(world, i + 3, j + 6, k + 57, block, 0);
		this.setBlock(world, i + 3, j + 6, k + 58, block, 0);
		this.setBlock(world, i + 3, j + 6, k + 59, block, 0);
		this.setBlock(world, i + 3, j + 7, k + 16, block, 0);
		this.setBlock(world, i + 3, j + 7, k + 17, block, 0);
		this.setBlock(world, i + 3, j + 7, k + 18, block, 0);
		this.setBlock(world, i + 3, j + 7, k + 19, block, 0);
		this.setBlock(world, i + 3, j + 7, k + 20, block, 0);
		this.setBlock(world, i + 3, j + 7, k + 21, block, 0);
		this.setBlock(world, i + 3, j + 7, k + 22, block, 0);
		this.setBlock(world, i + 3, j + 7, k + 23, block, 0);
		this.setBlock(world, i + 3, j + 7, k + 24, block, 0);
		this.setBlock(world, i + 3, j + 7, k + 25, block, 0);
		this.setBlock(world, i + 3, j + 7, k + 26, block, 0);
		this.setBlock(world, i + 3, j + 7, k + 43, block, 0);
		this.setBlock(world, i + 3, j + 7, k + 44, block, 0);
		this.setBlock(world, i + 3, j + 7, k + 45, block, 0);
		this.setBlock(world, i + 3, j + 7, k + 46, block, 0);
		this.setBlock(world, i + 3, j + 7, k + 47, block, 0);
		this.setBlock(world, i + 3, j + 7, k + 48, block, 0);
		this.setBlock(world, i + 3, j + 7, k + 49, block, 0);
		this.setBlock(world, i + 3, j + 7, k + 50, block, 0);
		this.setBlock(world, i + 3, j + 7, k + 51, block, 0);
		this.setBlock(world, i + 3, j + 7, k + 52, block, 0);
		this.setBlock(world, i + 3, j + 7, k + 53, block, 0);
		this.setBlock(world, i + 3, j + 7, k + 54, block, 0);
		this.setBlock(world, i + 3, j + 7, k + 55, block, 0);
		this.setBlock(world, i + 3, j + 7, k + 56, block, 0);
		this.setBlock(world, i + 3, j + 7, k + 57, block, 0);
		this.setBlock(world, i + 3, j + 7, k + 58, block, 0);
		this.setBlock(world, i + 3, j + 7, k + 59, block, 0);
		this.setBlock(world, i + 3, j + 8, k + 16, block, 0);
		this.setBlock(world, i + 3, j + 8, k + 17, block, 0);
		this.setBlock(world, i + 3, j + 8, k + 18, block, 0);
		this.setBlock(world, i + 3, j + 8, k + 19, block, 0);
		this.setBlock(world, i + 3, j + 8, k + 20, block, 0);
		this.setBlock(world, i + 3, j + 8, k + 21, block, 0);
		this.setBlock(world, i + 3, j + 8, k + 22, block, 0);
		this.setBlock(world, i + 3, j + 8, k + 23, block, 0);
		this.setBlock(world, i + 3, j + 8, k + 24, block, 0);
		this.setBlock(world, i + 3, j + 8, k + 25, block, 0);
		this.setBlock(world, i + 3, j + 8, k + 26, block, 0);
		this.setBlock(world, i + 3, j + 8, k + 43, block, 0);
		this.setBlock(world, i + 3, j + 8, k + 44, block, 0);
		this.setBlock(world, i + 3, j + 8, k + 45, block, 0);
		this.setBlock(world, i + 3, j + 8, k + 46, block, 0);
		this.setBlock(world, i + 3, j + 8, k + 47, block, 0);
		this.setBlock(world, i + 3, j + 8, k + 48, block, 0);
		this.setBlock(world, i + 3, j + 8, k + 49, block, 0);
		this.setBlock(world, i + 3, j + 8, k + 50, block, 0);
		this.setBlock(world, i + 3, j + 8, k + 51, block, 0);
		this.setBlock(world, i + 3, j + 8, k + 52, block, 0);
		this.setBlock(world, i + 3, j + 8, k + 53, block, 0);
		this.setBlock(world, i + 3, j + 8, k + 54, block, 0);
		this.setBlock(world, i + 3, j + 8, k + 55, block, 0);
		this.setBlock(world, i + 3, j + 8, k + 56, block, 0);
		this.setBlock(world, i + 3, j + 8, k + 57, block, 0);
		this.setBlock(world, i + 3, j + 8, k + 58, block, 0);
		this.setBlock(world, i + 3, j + 8, k + 59, block, 0);
		this.setBlock(world, i + 3, j + 9, k + 16, block, 0);
		this.setBlock(world, i + 3, j + 9, k + 17, block, 0);
		this.setBlock(world, i + 3, j + 9, k + 18, block, 0);
		this.setBlock(world, i + 3, j + 9, k + 19, block, 0);
		this.setBlock(world, i + 3, j + 9, k + 20, block, 0);
		this.setBlock(world, i + 3, j + 9, k + 21, block, 0);
		this.setBlock(world, i + 3, j + 9, k + 22, block, 0);
		this.setBlock(world, i + 3, j + 9, k + 23, block, 0);
		this.setBlock(world, i + 3, j + 9, k + 24, block, 0);
		this.setBlock(world, i + 3, j + 9, k + 25, block, 0);
		this.setBlock(world, i + 3, j + 9, k + 26, block, 0);
		this.setBlock(world, i + 3, j + 9, k + 43, block, 0);
		this.setBlock(world, i + 3, j + 9, k + 44, block, 0);
		this.setBlock(world, i + 3, j + 9, k + 45, block, 0);
		this.setBlock(world, i + 3, j + 9, k + 46, block, 0);
		this.setBlock(world, i + 3, j + 9, k + 47, block, 0);
		this.setBlock(world, i + 3, j + 9, k + 48, block, 0);
		this.setBlock(world, i + 3, j + 9, k + 49, block, 0);
		this.setBlock(world, i + 3, j + 9, k + 50, block, 0);
		this.setBlock(world, i + 3, j + 9, k + 51, block, 0);
		this.setBlock(world, i + 3, j + 9, k + 52, block, 0);
		this.setBlock(world, i + 3, j + 9, k + 53, block, 0);
		this.setBlock(world, i + 3, j + 9, k + 54, block, 0);
		this.setBlock(world, i + 3, j + 9, k + 55, block, 0);
		this.setBlock(world, i + 3, j + 9, k + 56, block, 0);
		this.setBlock(world, i + 3, j + 9, k + 57, block, 0);
		this.setBlock(world, i + 3, j + 9, k + 58, block, 0);
		this.setBlock(world, i + 3, j + 9, k + 59, block, 0);
		this.setBlock(world, i + 3, j + 10, k + 17, slabBlock, 0);
		this.setBlock(world, i + 3, j + 10, k + 18, block, 0);
		this.setBlock(world, i + 3, j + 10, k + 19, block, 0);
		this.setBlock(world, i + 3, j + 10, k + 20, block, 0);
		this.setBlock(world, i + 3, j + 10, k + 21, block, 0);
		this.setBlock(world, i + 3, j + 10, k + 22, block, 0);
		this.setBlock(world, i + 3, j + 10, k + 23, block, 0);
		this.setBlock(world, i + 3, j + 10, k + 24, block, 0);
		this.setBlock(world, i + 3, j + 10, k + 25, slabBlock, 0);
		this.setBlock(world, i + 3, j + 10, k + 44, block, 0);
		this.setBlock(world, i + 3, j + 10, k + 45, block, 0);
		this.setBlock(world, i + 3, j + 10, k + 46, block, 0);
		this.setBlock(world, i + 3, j + 10, k + 47, block, 0);
		this.setBlock(world, i + 3, j + 10, k + 48, block, 0);
		this.setBlock(world, i + 3, j + 10, k + 49, block, 0);
		this.setBlock(world, i + 3, j + 10, k + 50, block, 0);
		this.setBlock(world, i + 3, j + 10, k + 51, block, 0);
		this.setBlock(world, i + 3, j + 10, k + 52, block, 0);
		this.setBlock(world, i + 3, j + 10, k + 53, block, 0);
		this.setBlock(world, i + 3, j + 10, k + 54, block, 0);
		this.setBlock(world, i + 3, j + 10, k + 55, block, 0);
		this.setBlock(world, i + 3, j + 10, k + 56, block, 0);
		this.setBlock(world, i + 3, j + 10, k + 57, block, 0);
		this.setBlock(world, i + 3, j + 10, k + 58, block, 0);
		this.setBlock(world, i + 4, j + 0, k + 17, block, 0);
		this.setBlock(world, i + 4, j + 0, k + 18, block, 0);
		this.setBlock(world, i + 4, j + 0, k + 19, block, 0);
		this.setBlock(world, i + 4, j + 0, k + 20, block, 0);
		this.setBlock(world, i + 4, j + 0, k + 21, block, 0);
		this.setBlock(world, i + 4, j + 0, k + 22, block, 0);
		this.setBlock(world, i + 4, j + 0, k + 23, block, 0);
		this.setBlock(world, i + 4, j + 0, k + 24, block, 0);
		this.setBlock(world, i + 4, j + 0, k + 25, block, 0);
		this.setBlock(world, i + 4, j + 0, k + 44, block, 0);
		this.setBlock(world, i + 4, j + 0, k + 45, block, 0);
		this.setBlock(world, i + 4, j + 0, k + 46, block, 0);
		this.setBlock(world, i + 4, j + 0, k + 47, block, 0);
		this.setBlock(world, i + 4, j + 0, k + 48, block, 0);
		this.setBlock(world, i + 4, j + 0, k + 49, block, 0);
		this.setBlock(world, i + 4, j + 0, k + 50, block, 0);
		this.setBlock(world, i + 4, j + 0, k + 51, block, 0);
		this.setBlock(world, i + 4, j + 0, k + 52, block, 0);
		this.setBlock(world, i + 4, j + 0, k + 53, block, 0);
		this.setBlock(world, i + 4, j + 0, k + 54, block, 0);
		this.setBlock(world, i + 4, j + 0, k + 55, block, 0);
		this.setBlock(world, i + 4, j + 0, k + 56, block, 0);
		this.setBlock(world, i + 4, j + 0, k + 57, block, 0);
		this.setBlock(world, i + 4, j + 0, k + 58, block, 0);
		this.setBlock(world, i + 4, j + 1, k + 16, block, 0);
		this.setBlock(world, i + 4, j + 1, k + 17, Blocks.air, 0);
		this.setBlock(world, i + 4, j + 1, k + 18, Blocks.air, 0);
		this.setBlock(world, i + 4, j + 1, k + 19, Blocks.air, 0);
		this.setBlock(world, i + 4, j + 1, k + 20, Blocks.air, 0);
		this.setBlock(world, i + 4, j + 1, k + 21, block, 0);
		this.setBlock(world, i + 4, j + 1, k + 22, Blocks.air, 0);
		this.setBlock(world, i + 4, j + 1, k + 23, Blocks.air, 0);
		this.setBlock(world, i + 4, j + 1, k + 24, Blocks.air, 0);
		this.setBlock(world, i + 4, j + 1, k + 25, Blocks.air, 0);
		this.setBlock(world, i + 4, j + 1, k + 26, block, 0);
		this.setBlock(world, i + 4, j + 1, k + 43, block, 0);
		this.setBlock(world, i + 4, j + 1, k + 44, Blocks.air, 0);
		this.setBlock(world, i + 4, j + 1, k + 45, block, 0);
		this.setBlock(world, i + 4, j + 1, k + 46, block, 0);
		this.setBlock(world, i + 4, j + 1, k + 47, block, 0);
		this.setBlock(world, i + 4, j + 1, k + 48, block, 0);
		this.setBlock(world, i + 4, j + 1, k + 49, block, 0);
		this.setBlock(world, i + 4, j + 1, k + 50, block, 0);
		this.setBlock(world, i + 4, j + 1, k + 51, block, 0);
		this.setBlock(world, i + 4, j + 1, k + 52, Blocks.air, 0);
		this.setBlock(world, i + 4, j + 1, k + 53, Blocks.air, 0);
		this.setBlock(world, i + 4, j + 1, k + 54, Blocks.air, 0);
		this.setBlock(world, i + 4, j + 1, k + 55, Blocks.air, 0);
		this.setBlock(world, i + 4, j + 1, k + 56, Blocks.air, 0);
		this.setBlock(world, i + 4, j + 1, k + 57, Blocks.air, 0);
		this.setBlock(world, i + 4, j + 1, k + 58, Blocks.air, 0);
		this.setBlock(world, i + 4, j + 1, k + 59, block, 0);
		this.setBlock(world, i + 4, j + 2, k + 16, block, 0);
		this.setBlock(world, i + 4, j + 2, k + 21, block, 0);
		this.setBlock(world, i + 4, j + 2, k + 26, block, 0);
		this.setBlock(world, i + 4, j + 2, k + 43, block, 0);
		this.setBlock(world, i + 4, j + 2, k + 45, block, 0);
		this.setBlock(world, i + 4, j + 2, k + 46, block, 0);
		this.setBlock(world, i + 4, j + 2, k + 47, block, 0);
		this.setBlock(world, i + 4, j + 2, k + 48, block, 0);
		this.setBlock(world, i + 4, j + 2, k + 49, block, 0);
		this.setBlock(world, i + 4, j + 2, k + 50, block, 0);
		this.setBlock(world, i + 4, j + 2, k + 51, block, 0);
		this.setBlock(world, i + 4, j + 2, k + 59, block, 0);
		this.setBlock(world, i + 4, j + 3, k + 16, block, 0);
		this.setBlock(world, i + 4, j + 3, k + 21, block, 0);
		this.setBlock(world, i + 4, j + 3, k + 26, block, 0);
		this.setBlock(world, i + 4, j + 3, k + 43, block, 0);
		this.setBlock(world, i + 4, j + 3, k + 45, block, 0);
		this.setBlock(world, i + 4, j + 3, k + 46, block, 0);
		this.setBlock(world, i + 4, j + 3, k + 47, block, 0);
		this.setBlock(world, i + 4, j + 3, k + 48, block, 0);
		this.setBlock(world, i + 4, j + 3, k + 49, block, 0);
		this.setBlock(world, i + 4, j + 3, k + 50, block, 0);
		this.setBlock(world, i + 4, j + 3, k + 51, block, 0);
		this.setBlock(world, i + 4, j + 3, k + 59, block, 0);
		this.setBlock(world, i + 4, j + 4, k + 16, block, 0);
		this.setBlock(world, i + 4, j + 4, k + 21, block, 0);
		this.setBlock(world, i + 4, j + 4, k + 26, block, 0);
		this.setBlock(world, i + 4, j + 4, k + 43, block, 0);
		this.setBlock(world, i + 4, j + 4, k + 44, slabBlock, 8);
		this.setBlock(world, i + 4, j + 4, k + 45, block, 0);
		this.setBlock(world, i + 4, j + 4, k + 46, block, 0);
		this.setBlock(world, i + 4, j + 4, k + 47, block, 0);
		this.setBlock(world, i + 4, j + 4, k + 48, block, 0);
		this.setBlock(world, i + 4, j + 4, k + 49, block, 0);
		this.setBlock(world, i + 4, j + 4, k + 50, block, 0);
		this.setBlock(world, i + 4, j + 4, k + 51, block, 0);
		this.setBlock(world, i + 4, j + 4, k + 58, Blocks.iron_bars, 0);
		this.setBlock(world, i + 4, j + 4, k + 59, block, 0);
		this.setBlock(world, i + 4, j + 5, k + 16, block, 0);
		this.setBlock(world, i + 4, j + 5, k + 17, block, 0);
		this.setBlock(world, i + 4, j + 5, k + 18, block, 0);
		this.setBlock(world, i + 4, j + 5, k + 19, block, 0);
		this.setBlock(world, i + 4, j + 5, k + 20, block, 0);
		this.setBlock(world, i + 4, j + 5, k + 21, block, 0);
		this.setBlock(world, i + 4, j + 5, k + 22, block, 0);
		this.setBlock(world, i + 4, j + 5, k + 23, block, 0);
		this.setBlock(world, i + 4, j + 5, k + 24, block, 0);
		this.setBlock(world, i + 4, j + 5, k + 25, block, 0);
		this.setBlock(world, i + 4, j + 5, k + 26, block, 0);
		this.setBlock(world, i + 4, j + 5, k + 43, block, 0);
		this.setBlock(world, i + 4, j + 5, k + 44, block, 0);
		this.setBlock(world, i + 4, j + 5, k + 45, block, 0);
		this.setBlock(world, i + 4, j + 5, k + 46, block, 0);
		this.setBlock(world, i + 4, j + 5, k + 47, block, 0);
		this.setBlock(world, i + 4, j + 5, k + 48, block, 0);
		this.setBlock(world, i + 4, j + 5, k + 49, block, 0);
		this.setBlock(world, i + 4, j + 5, k + 50, block, 0);
		this.setBlock(world, i + 4, j + 5, k + 51, block, 0);
		this.setBlock(world, i + 4, j + 5, k + 52, block, 0);
		this.setBlock(world, i + 4, j + 5, k + 53, block, 0);
		this.setBlock(world, i + 4, j + 5, k + 54, stairBlock, 5);
		this.setBlock(world, i + 4, j + 5, k + 55, stairBlock, 5);
		this.setBlock(world, i + 4, j + 5, k + 56, block, 0);
		this.setBlock(world, i + 4, j + 5, k + 57, block, 0);
		this.setBlock(world, i + 4, j + 5, k + 58, block, 0);
		this.setBlock(world, i + 4, j + 5, k + 59, block, 0);
		this.setBlock(world, i + 4, j + 6, k + 16, block, 0);
		this.setBlock(world, i + 4, j + 6, k + 17, block, 0);
		this.setBlock(world, i + 4, j + 6, k + 18, block, 0);
		this.setBlock(world, i + 4, j + 6, k + 19, block, 0);
		this.setBlock(world, i + 4, j + 6, k + 20, block, 0);
		this.setBlock(world, i + 4, j + 6, k + 21, block, 0);
		this.setBlock(world, i + 4, j + 6, k + 22, block, 0);
		this.setBlock(world, i + 4, j + 6, k + 23, block, 0);
		this.setBlock(world, i + 4, j + 6, k + 24, block, 0);
		this.setBlock(world, i + 4, j + 6, k + 25, block, 0);
		this.setBlock(world, i + 4, j + 6, k + 26, block, 0);
		this.setBlock(world, i + 4, j + 6, k + 43, block, 0);
		this.setBlock(world, i + 4, j + 6, k + 44, block, 0);
		this.setBlock(world, i + 4, j + 6, k + 45, block, 0);
		this.setBlock(world, i + 4, j + 6, k + 46, block, 0);
		this.setBlock(world, i + 4, j + 6, k + 47, block, 0);
		this.setBlock(world, i + 4, j + 6, k + 48, block, 0);
		this.setBlock(world, i + 4, j + 6, k + 49, block, 0);
		this.setBlock(world, i + 4, j + 6, k + 50, block, 0);
		this.setBlock(world, i + 4, j + 6, k + 51, block, 0);
		this.setBlock(world, i + 4, j + 6, k + 52, block, 0);
		this.setBlock(world, i + 4, j + 6, k + 53, block, 0);
		this.setBlock(world, i + 4, j + 6, k + 54, block, 0);
		this.setBlock(world, i + 4, j + 6, k + 55, block, 0);
		this.setBlock(world, i + 4, j + 6, k + 56, block, 0);
		this.setBlock(world, i + 4, j + 6, k + 57, block, 0);
		this.setBlock(world, i + 4, j + 6, k + 58, block, 0);
		this.setBlock(world, i + 4, j + 6, k + 59, block, 0);
		this.setBlock(world, i + 4, j + 7, k + 16, block, 0);
		this.setBlock(world, i + 4, j + 7, k + 17, block, 0);
		this.setBlock(world, i + 4, j + 7, k + 18, block, 0);
		this.setBlock(world, i + 4, j + 7, k + 19, block, 0);
		this.setBlock(world, i + 4, j + 7, k + 20, block, 0);
		this.setBlock(world, i + 4, j + 7, k + 21, block, 0);
		this.setBlock(world, i + 4, j + 7, k + 22, block, 0);
		this.setBlock(world, i + 4, j + 7, k + 23, block, 0);
		this.setBlock(world, i + 4, j + 7, k + 24, block, 0);
		this.setBlock(world, i + 4, j + 7, k + 25, block, 0);
		this.setBlock(world, i + 4, j + 7, k + 26, block, 0);
		this.setBlock(world, i + 4, j + 7, k + 43, block, 0);
		this.setBlock(world, i + 4, j + 7, k + 44, block, 0);
		this.setBlock(world, i + 4, j + 7, k + 45, block, 0);
		this.setBlock(world, i + 4, j + 7, k + 46, block, 0);
		this.setBlock(world, i + 4, j + 7, k + 47, block, 0);
		this.setBlock(world, i + 4, j + 7, k + 48, block, 0);
		this.setBlock(world, i + 4, j + 7, k + 49, block, 0);
		this.setBlock(world, i + 4, j + 7, k + 50, block, 0);
		this.setBlock(world, i + 4, j + 7, k + 51, block, 0);
		this.setBlock(world, i + 4, j + 7, k + 52, block, 0);
		this.setBlock(world, i + 4, j + 7, k + 53, block, 0);
		this.setBlock(world, i + 4, j + 7, k + 54, block, 0);
		this.setBlock(world, i + 4, j + 7, k + 55, block, 0);
		this.setBlock(world, i + 4, j + 7, k + 56, block, 0);
		this.setBlock(world, i + 4, j + 7, k + 57, block, 0);
		this.setBlock(world, i + 4, j + 7, k + 58, block, 0);
		this.setBlock(world, i + 4, j + 7, k + 59, block, 0);
		this.setBlock(world, i + 4, j + 8, k + 16, block, 0);
		this.setBlock(world, i + 4, j + 8, k + 17, block, 0);
		this.setBlock(world, i + 4, j + 8, k + 18, block, 0);
		this.setBlock(world, i + 4, j + 8, k + 19, block, 0);
		this.setBlock(world, i + 4, j + 8, k + 20, block, 0);
		this.setBlock(world, i + 4, j + 8, k + 21, block, 0);
		this.setBlock(world, i + 4, j + 8, k + 22, block, 0);
		this.setBlock(world, i + 4, j + 8, k + 23, block, 0);
		this.setBlock(world, i + 4, j + 8, k + 24, block, 0);
		this.setBlock(world, i + 4, j + 8, k + 25, block, 0);
		this.setBlock(world, i + 4, j + 8, k + 26, block, 0);
		this.setBlock(world, i + 4, j + 8, k + 43, block, 0);
		this.setBlock(world, i + 4, j + 8, k + 44, block, 0);
		this.setBlock(world, i + 4, j + 8, k + 45, block, 0);
		this.setBlock(world, i + 4, j + 8, k + 46, block, 0);
		this.setBlock(world, i + 4, j + 8, k + 47, block, 0);
		this.setBlock(world, i + 4, j + 8, k + 48, block, 0);
		this.setBlock(world, i + 4, j + 8, k + 49, block, 0);
		this.setBlock(world, i + 4, j + 8, k + 50, block, 0);
		this.setBlock(world, i + 4, j + 8, k + 51, block, 0);
		this.setBlock(world, i + 4, j + 8, k + 52, block, 0);
		this.setBlock(world, i + 4, j + 8, k + 53, block, 0);
		this.setBlock(world, i + 4, j + 8, k + 54, block, 0);
		this.setBlock(world, i + 4, j + 8, k + 55, block, 0);
		this.setBlock(world, i + 4, j + 8, k + 56, block, 0);
		this.setBlock(world, i + 4, j + 8, k + 57, block, 0);
		this.setBlock(world, i + 4, j + 8, k + 58, block, 0);
		this.setBlock(world, i + 4, j + 8, k + 59, block, 0);
		this.setBlock(world, i + 4, j + 9, k + 16, block, 0);
		this.setBlock(world, i + 4, j + 9, k + 17, block, 0);
		this.setBlock(world, i + 4, j + 9, k + 18, block, 0);
		this.setBlock(world, i + 4, j + 9, k + 19, block, 0);
		this.setBlock(world, i + 4, j + 9, k + 20, block, 0);
		this.setBlock(world, i + 4, j + 9, k + 21, block, 0);
		this.setBlock(world, i + 4, j + 9, k + 22, block, 0);
		this.setBlock(world, i + 4, j + 9, k + 23, block, 0);
		this.setBlock(world, i + 4, j + 9, k + 24, block, 0);
		this.setBlock(world, i + 4, j + 9, k + 25, block, 0);
		this.setBlock(world, i + 4, j + 9, k + 26, block, 0);
		this.setBlock(world, i + 4, j + 9, k + 43, block, 0);
		this.setBlock(world, i + 4, j + 9, k + 44, block, 0);
		this.setBlock(world, i + 4, j + 9, k + 45, block, 0);
		this.setBlock(world, i + 4, j + 9, k + 46, block, 0);
		this.setBlock(world, i + 4, j + 9, k + 47, block, 0);
		this.setBlock(world, i + 4, j + 9, k + 48, block, 0);
		this.setBlock(world, i + 4, j + 9, k + 49, block, 0);
		this.setBlock(world, i + 4, j + 9, k + 50, block, 0);
		this.setBlock(world, i + 4, j + 9, k + 51, block, 0);
		this.setBlock(world, i + 4, j + 9, k + 52, block, 0);
		this.setBlock(world, i + 4, j + 9, k + 53, block, 0);
		this.setBlock(world, i + 4, j + 9, k + 54, block, 0);
		this.setBlock(world, i + 4, j + 9, k + 55, block, 0);
		this.setBlock(world, i + 4, j + 9, k + 56, block, 0);
		this.setBlock(world, i + 4, j + 9, k + 57, block, 0);
		this.setBlock(world, i + 4, j + 9, k + 58, block, 0);
		this.setBlock(world, i + 4, j + 9, k + 59, block, 0);
		this.setBlock(world, i + 4, j + 10, k + 17, block, 0);
		this.setBlock(world, i + 4, j + 10, k + 18, block, 0);
		this.setBlock(world, i + 4, j + 10, k + 19, block, 0);
		this.setBlock(world, i + 4, j + 10, k + 20, block, 0);
		this.setBlock(world, i + 4, j + 10, k + 21, block, 0);
		this.setBlock(world, i + 4, j + 10, k + 22, block, 0);
		this.setBlock(world, i + 4, j + 10, k + 23, block, 0);
		this.setBlock(world, i + 4, j + 10, k + 24, block, 0);
		this.setBlock(world, i + 4, j + 10, k + 25, block, 0);
		this.setBlock(world, i + 4, j + 10, k + 44, block, 0);
		this.setBlock(world, i + 4, j + 10, k + 45, block, 0);
		this.setBlock(world, i + 4, j + 10, k + 46, block, 0);
		this.setBlock(world, i + 4, j + 10, k + 47, block, 0);
		this.setBlock(world, i + 4, j + 10, k + 48, block, 0);
		this.setBlock(world, i + 4, j + 10, k + 49, block, 0);
		this.setBlock(world, i + 4, j + 10, k + 50, block, 0);
		this.setBlock(world, i + 4, j + 10, k + 51, block, 0);
		this.setBlock(world, i + 4, j + 10, k + 52, block, 0);
		this.setBlock(world, i + 4, j + 10, k + 53, block, 0);
		this.setBlock(world, i + 4, j + 10, k + 54, block, 0);
		this.setBlock(world, i + 4, j + 10, k + 55, block, 0);
		this.setBlock(world, i + 4, j + 10, k + 56, block, 0);
		this.setBlock(world, i + 4, j + 10, k + 57, block, 0);
		this.setBlock(world, i + 4, j + 10, k + 58, block, 0);
		this.setBlock(world, i + 5, j + 0, k + 17, block, 0);
		this.setBlock(world, i + 5, j + 0, k + 18, block, 0);
		this.setBlock(world, i + 5, j + 0, k + 19, block, 0);
		this.setBlock(world, i + 5, j + 0, k + 20, block, 0);
		this.setBlock(world, i + 5, j + 0, k + 21, block, 0);
		this.setBlock(world, i + 5, j + 0, k + 22, block, 0);
		this.setBlock(world, i + 5, j + 0, k + 23, block, 0);
		this.setBlock(world, i + 5, j + 0, k + 24, block, 0);
		this.setBlock(world, i + 5, j + 0, k + 25, block, 0);
		this.setBlock(world, i + 5, j + 0, k + 44, block, 0);
		this.setBlock(world, i + 5, j + 0, k + 45, block, 0);
		this.setBlock(world, i + 5, j + 0, k + 46, block, 0);
		this.setBlock(world, i + 5, j + 0, k + 47, block, 0);
		this.setBlock(world, i + 5, j + 0, k + 48, block, 0);
		this.setBlock(world, i + 5, j + 0, k + 49, block, 0);
		this.setBlock(world, i + 5, j + 0, k + 50, block, 0);
		this.setBlock(world, i + 5, j + 0, k + 51, block, 0);
		this.setBlock(world, i + 5, j + 0, k + 52, block, 0);
		this.setBlock(world, i + 5, j + 0, k + 53, block, 0);
		this.setBlock(world, i + 5, j + 0, k + 54, block, 0);
		this.setBlock(world, i + 5, j + 0, k + 55, block, 0);
		this.setBlock(world, i + 5, j + 0, k + 56, block, 0);
		this.setBlock(world, i + 5, j + 0, k + 57, block, 0);
		this.setBlock(world, i + 5, j + 0, k + 58, block, 0);
		this.setBlock(world, i + 5, j + 1, k + 16, block, 0);
		this.setBlock(world, i + 5, j + 1, k + 17, Blocks.air, 0);
		this.setBlock(world, i + 5, j + 1, k + 18, Blocks.air, 0);
		this.setBlock(world, i + 5, j + 1, k + 19, Blocks.air, 0);
		this.setBlock(world, i + 5, j + 1, k + 20, Blocks.air, 0);
		this.setBlock(world, i + 5, j + 1, k + 21, block, 0);
		this.setBlock(world, i + 5, j + 1, k + 22, Blocks.chest, 3);
		this.setBlock(world, i + 5, j + 1, k + 23, Blocks.air, 0);
		this.setBlock(world, i + 5, j + 1, k + 24, Blocks.air, 0);
		this.setBlock(world, i + 5, j + 1, k + 25, Blocks.air, 0);
		this.setBlock(world, i + 5, j + 1, k + 26, block, 0);
		this.setBlock(world, i + 5, j + 1, k + 43, block, 0);
		this.setBlock(world, i + 5, j + 1, k + 44, Blocks.air, 0);
		this.setBlock(world, i + 5, j + 1, k + 45, Blocks.air, 0);
		this.setBlock(world, i + 5, j + 1, k + 46, Blocks.air, 0);
		this.setBlock(world, i + 5, j + 1, k + 47, Blocks.air, 0);
		this.setBlock(world, i + 5, j + 1, k + 48, Blocks.air, 0);
		this.setBlock(world, i + 5, j + 1, k + 49, Blocks.air, 0);
		this.setBlock(world, i + 5, j + 1, k + 50, Blocks.air, 0);
		this.setBlock(world, i + 5, j + 1, k + 51, block, 0);
		this.setBlock(world, i + 5, j + 1, k + 52, Blocks.air, 0);
		this.setBlock(world, i + 5, j + 1, k + 53, Blocks.air, 0);
		this.setBlock(world, i + 5, j + 1, k + 54, stairBlock, 0);
		this.setBlock(world, i + 5, j + 1, k + 55, stairBlock, 0);
		this.setBlock(world, i + 5, j + 1, k + 56, block, 0);
		this.setBlock(world, i + 5, j + 1, k + 57, block, 0);
		this.setBlock(world, i + 5, j + 1, k + 58, block, 0);
		this.setBlock(world, i + 5, j + 1, k + 59, block, 0);
		this.setBlock(world, i + 5, j + 2, k + 16, block, 0);
		this.setBlock(world, i + 5, j + 2, k + 21, block, 0);
		this.setBlock(world, i + 5, j + 2, k + 26, block, 0);
		this.setBlock(world, i + 5, j + 2, k + 43, block, 0);
		this.setBlock(world, i + 5, j + 2, k + 51, block, 0);
		this.setBlock(world, i + 5, j + 2, k + 56, block, 0);
		this.setBlock(world, i + 5, j + 2, k + 57, block, 0);
		this.setBlock(world, i + 5, j + 2, k + 58, block, 0);
		this.setBlock(world, i + 5, j + 2, k + 59, block, 0);
		this.setBlock(world, i + 5, j + 3, k + 16, block, 0);
		this.setBlock(world, i + 5, j + 3, k + 21, block, 0);
		this.setBlock(world, i + 5, j + 3, k + 26, block, 0);
		this.setBlock(world, i + 5, j + 3, k + 43, block, 0);
		this.setBlock(world, i + 5, j + 3, k + 51, block, 0);
		this.setBlock(world, i + 5, j + 3, k + 56, block, 0);
		this.setBlock(world, i + 5, j + 3, k + 57, block, 0);
		this.setBlock(world, i + 5, j + 3, k + 58, block, 0);
		this.setBlock(world, i + 5, j + 3, k + 59, block, 0);
		this.setBlock(world, i + 5, j + 4, k + 16, block, 0);
		this.setBlock(world, i + 5, j + 4, k + 21, block, 0);
		this.setBlock(world, i + 5, j + 4, k + 26, block, 0);
		this.setBlock(world, i + 5, j + 4, k + 43, block, 0);
		this.setBlock(world, i + 5, j + 4, k + 50, Blocks.iron_bars, 0);
		this.setBlock(world, i + 5, j + 4, k + 51, block, 0);
		this.setBlock(world, i + 5, j + 4, k + 56, block, 0);
		this.setBlock(world, i + 5, j + 4, k + 57, block, 0);
		this.setBlock(world, i + 5, j + 4, k + 58, block, 0);
		this.setBlock(world, i + 5, j + 4, k + 59, block, 0);
		this.setBlock(world, i + 5, j + 5, k + 16, block, 0);
		this.setBlock(world, i + 5, j + 5, k + 17, block, 0);
		this.setBlock(world, i + 5, j + 5, k + 18, block, 0);
		this.setBlock(world, i + 5, j + 5, k + 19, block, 0);
		this.setBlock(world, i + 5, j + 5, k + 20, block, 0);
		this.setBlock(world, i + 5, j + 5, k + 21, block, 0);
		this.setBlock(world, i + 5, j + 5, k + 22, block, 0);
		this.setBlock(world, i + 5, j + 5, k + 23, block, 0);
		this.setBlock(world, i + 5, j + 5, k + 24, block, 0);
		this.setBlock(world, i + 5, j + 5, k + 25, block, 0);
		this.setBlock(world, i + 5, j + 5, k + 26, block, 0);
		this.setBlock(world, i + 5, j + 5, k + 43, block, 0);
		this.setBlock(world, i + 5, j + 5, k + 44, block, 0);
		this.setBlock(world, i + 5, j + 5, k + 45, block, 0);
		this.setBlock(world, i + 5, j + 5, k + 46, block, 0);
		this.setBlock(world, i + 5, j + 5, k + 47, block, 0);
		this.setBlock(world, i + 5, j + 5, k + 48, block, 0);
		this.setBlock(world, i + 5, j + 5, k + 49, block, 0);
		this.setBlock(world, i + 5, j + 5, k + 50, block, 0);
		this.setBlock(world, i + 5, j + 5, k + 51, block, 0);
		this.setBlock(world, i + 5, j + 5, k + 52, block, 0);
		this.setBlock(world, i + 5, j + 5, k + 53, block, 0);
		this.setBlock(world, i + 5, j + 5, k + 56, block, 0);
		this.setBlock(world, i + 5, j + 5, k + 57, block, 0);
		this.setBlock(world, i + 5, j + 5, k + 58, block, 0);
		this.setBlock(world, i + 5, j + 5, k + 59, block, 0);
		this.setBlock(world, i + 5, j + 6, k + 16, block, 0);
		this.setBlock(world, i + 5, j + 6, k + 17, block, 0);
		this.setBlock(world, i + 5, j + 6, k + 18, block, 0);
		this.setBlock(world, i + 5, j + 6, k + 19, block, 0);
		this.setBlock(world, i + 5, j + 6, k + 20, block, 0);
		this.setBlock(world, i + 5, j + 6, k + 21, block, 0);
		this.setBlock(world, i + 5, j + 6, k + 22, block, 0);
		this.setBlock(world, i + 5, j + 6, k + 23, block, 0);
		this.setBlock(world, i + 5, j + 6, k + 24, block, 0);
		this.setBlock(world, i + 5, j + 6, k + 25, block, 0);
		this.setBlock(world, i + 5, j + 6, k + 26, block, 0);
		this.setBlock(world, i + 5, j + 6, k + 43, block, 0);
		this.setBlock(world, i + 5, j + 6, k + 44, block, 0);
		this.setBlock(world, i + 5, j + 6, k + 45, block, 0);
		this.setBlock(world, i + 5, j + 6, k + 46, block, 0);
		this.setBlock(world, i + 5, j + 6, k + 47, block, 0);
		this.setBlock(world, i + 5, j + 6, k + 48, block, 0);
		this.setBlock(world, i + 5, j + 6, k + 49, block, 0);
		this.setBlock(world, i + 5, j + 6, k + 50, block, 0);
		this.setBlock(world, i + 5, j + 6, k + 51, block, 0);
		this.setBlock(world, i + 5, j + 6, k + 52, block, 0);
		this.setBlock(world, i + 5, j + 6, k + 53, block, 0);
		this.setBlock(world, i + 5, j + 6, k + 54, stairBlock, 5);
		this.setBlock(world, i + 5, j + 6, k + 55, stairBlock, 5);
		this.setBlock(world, i + 5, j + 6, k + 56, block, 0);
		this.setBlock(world, i + 5, j + 6, k + 57, block, 0);
		this.setBlock(world, i + 5, j + 6, k + 58, block, 0);
		this.setBlock(world, i + 5, j + 6, k + 59, block, 0);
		this.setBlock(world, i + 5, j + 7, k + 16, block, 0);
		this.setBlock(world, i + 5, j + 7, k + 17, block, 0);
		this.setBlock(world, i + 5, j + 7, k + 18, block, 0);
		this.setBlock(world, i + 5, j + 7, k + 19, block, 0);
		this.setBlock(world, i + 5, j + 7, k + 20, block, 0);
		this.setBlock(world, i + 5, j + 7, k + 21, block, 0);
		this.setBlock(world, i + 5, j + 7, k + 22, block, 0);
		this.setBlock(world, i + 5, j + 7, k + 23, block, 0);
		this.setBlock(world, i + 5, j + 7, k + 24, block, 0);
		this.setBlock(world, i + 5, j + 7, k + 25, block, 0);
		this.setBlock(world, i + 5, j + 7, k + 26, block, 0);
		this.setBlock(world, i + 5, j + 7, k + 43, block, 0);
		this.setBlock(world, i + 5, j + 7, k + 44, block, 0);
		this.setBlock(world, i + 5, j + 7, k + 45, block, 0);
		this.setBlock(world, i + 5, j + 7, k + 46, block, 0);
		this.setBlock(world, i + 5, j + 7, k + 47, block, 0);
		this.setBlock(world, i + 5, j + 7, k + 48, block, 0);
		this.setBlock(world, i + 5, j + 7, k + 49, block, 0);
		this.setBlock(world, i + 5, j + 7, k + 50, block, 0);
		this.setBlock(world, i + 5, j + 7, k + 51, block, 0);
		this.setBlock(world, i + 5, j + 7, k + 52, block, 0);
		this.setBlock(world, i + 5, j + 7, k + 53, block, 0);
		this.setBlock(world, i + 5, j + 7, k + 54, block, 0);
		this.setBlock(world, i + 5, j + 7, k + 55, block, 0);
		this.setBlock(world, i + 5, j + 7, k + 56, block, 0);
		this.setBlock(world, i + 5, j + 7, k + 57, block, 0);
		this.setBlock(world, i + 5, j + 7, k + 58, block, 0);
		this.setBlock(world, i + 5, j + 7, k + 59, block, 0);
		this.setBlock(world, i + 5, j + 8, k + 16, block, 0);
		this.setBlock(world, i + 5, j + 8, k + 17, block, 0);
		this.setBlock(world, i + 5, j + 8, k + 18, block, 0);
		this.setBlock(world, i + 5, j + 8, k + 19, block, 0);
		this.setBlock(world, i + 5, j + 8, k + 20, block, 0);
		this.setBlock(world, i + 5, j + 8, k + 21, block, 0);
		this.setBlock(world, i + 5, j + 8, k + 22, block, 0);
		this.setBlock(world, i + 5, j + 8, k + 23, block, 0);
		this.setBlock(world, i + 5, j + 8, k + 24, block, 0);
		this.setBlock(world, i + 5, j + 8, k + 25, block, 0);
		this.setBlock(world, i + 5, j + 8, k + 26, block, 0);
		this.setBlock(world, i + 5, j + 8, k + 43, block, 0);
		this.setBlock(world, i + 5, j + 8, k + 44, block, 0);
		this.setBlock(world, i + 5, j + 8, k + 45, block, 0);
		this.setBlock(world, i + 5, j + 8, k + 46, block, 0);
		this.setBlock(world, i + 5, j + 8, k + 47, block, 0);
		this.setBlock(world, i + 5, j + 8, k + 48, block, 0);
		this.setBlock(world, i + 5, j + 8, k + 49, block, 0);
		this.setBlock(world, i + 5, j + 8, k + 50, block, 0);
		this.setBlock(world, i + 5, j + 8, k + 51, block, 0);
		this.setBlock(world, i + 5, j + 8, k + 52, block, 0);
		this.setBlock(world, i + 5, j + 8, k + 53, block, 0);
		this.setBlock(world, i + 5, j + 8, k + 54, block, 0);
		this.setBlock(world, i + 5, j + 8, k + 55, block, 0);
		this.setBlock(world, i + 5, j + 8, k + 56, block, 0);
		this.setBlock(world, i + 5, j + 8, k + 57, block, 0);
		this.setBlock(world, i + 5, j + 8, k + 58, block, 0);
		this.setBlock(world, i + 5, j + 8, k + 59, block, 0);
		this.setBlock(world, i + 5, j + 9, k + 16, block, 0);
		this.setBlock(world, i + 5, j + 9, k + 17, block, 0);
		this.setBlock(world, i + 5, j + 9, k + 18, block, 0);
		this.setBlock(world, i + 5, j + 9, k + 19, block, 0);
		this.setBlock(world, i + 5, j + 9, k + 20, block, 0);
		this.setBlock(world, i + 5, j + 9, k + 21, block, 0);
		this.setBlock(world, i + 5, j + 9, k + 22, block, 0);
		this.setBlock(world, i + 5, j + 9, k + 23, block, 0);
		this.setBlock(world, i + 5, j + 9, k + 24, block, 0);
		this.setBlock(world, i + 5, j + 9, k + 25, block, 0);
		this.setBlock(world, i + 5, j + 9, k + 26, block, 0);
		this.setBlock(world, i + 5, j + 9, k + 43, block, 0);
		this.setBlock(world, i + 5, j + 9, k + 44, block, 0);
		this.setBlock(world, i + 5, j + 9, k + 45, block, 0);
		this.setBlock(world, i + 5, j + 9, k + 46, block, 0);
		this.setBlock(world, i + 5, j + 9, k + 47, block, 0);
		this.setBlock(world, i + 5, j + 9, k + 48, block, 0);
		this.setBlock(world, i + 5, j + 9, k + 49, block, 0);
		this.setBlock(world, i + 5, j + 9, k + 50, block, 0);
		this.setBlock(world, i + 5, j + 9, k + 51, block, 0);
		this.setBlock(world, i + 5, j + 9, k + 52, block, 0);
		this.setBlock(world, i + 5, j + 9, k + 53, block, 0);
		this.setBlock(world, i + 5, j + 9, k + 54, block, 0);
		this.setBlock(world, i + 5, j + 9, k + 55, block, 0);
		this.setBlock(world, i + 5, j + 9, k + 56, block, 0);
		this.setBlock(world, i + 5, j + 9, k + 57, block, 0);
		this.setBlock(world, i + 5, j + 9, k + 58, block, 0);
		this.setBlock(world, i + 5, j + 9, k + 59, block, 0);
		this.setBlock(world, i + 5, j + 10, k + 17, block, 0);
		this.setBlock(world, i + 5, j + 10, k + 18, block, 0);
		this.setBlock(world, i + 5, j + 10, k + 19, block, 0);
		this.setBlock(world, i + 5, j + 10, k + 20, block, 0);
		this.setBlock(world, i + 5, j + 10, k + 21, block, 0);
		this.setBlock(world, i + 5, j + 10, k + 22, block, 0);
		this.setBlock(world, i + 5, j + 10, k + 23, block, 0);
		this.setBlock(world, i + 5, j + 10, k + 24, block, 0);
		this.setBlock(world, i + 5, j + 10, k + 25, block, 0);
		this.setBlock(world, i + 5, j + 10, k + 44, block, 0);
		this.setBlock(world, i + 5, j + 10, k + 45, block, 0);
		this.setBlock(world, i + 5, j + 10, k + 46, block, 0);
		this.setBlock(world, i + 5, j + 10, k + 47, block, 0);
		this.setBlock(world, i + 5, j + 10, k + 48, block, 0);
		this.setBlock(world, i + 5, j + 10, k + 49, block, 0);
		this.setBlock(world, i + 5, j + 10, k + 50, block, 0);
		this.setBlock(world, i + 5, j + 10, k + 51, block, 0);
		this.setBlock(world, i + 5, j + 10, k + 52, block, 0);
		this.setBlock(world, i + 5, j + 10, k + 53, block, 0);
		this.setBlock(world, i + 5, j + 10, k + 54, block, 0);
		this.setBlock(world, i + 5, j + 10, k + 55, block, 0);
		this.setBlock(world, i + 5, j + 10, k + 56, block, 0);
		this.setBlock(world, i + 5, j + 10, k + 57, block, 0);
		this.setBlock(world, i + 5, j + 10, k + 58, block, 0);
		this.setBlock(world, i + 6, j + 0, k + 17, block, 0);
		this.setBlock(world, i + 6, j + 0, k + 18, block, 0);
		this.setBlock(world, i + 6, j + 0, k + 19, block, 0);
		this.setBlock(world, i + 6, j + 0, k + 20, block, 0);
		this.setBlock(world, i + 6, j + 0, k + 21, block, 0);
		this.setBlock(world, i + 6, j + 0, k + 22, block, 0);
		this.setBlock(world, i + 6, j + 0, k + 23, block, 0);
		this.setBlock(world, i + 6, j + 0, k + 24, block, 0);
		this.setBlock(world, i + 6, j + 0, k + 25, block, 0);
		this.setBlock(world, i + 6, j + 0, k + 44, block, 0);
		this.setBlock(world, i + 6, j + 0, k + 45, block, 0);
		this.setBlock(world, i + 6, j + 0, k + 46, block, 0);
		this.setBlock(world, i + 6, j + 0, k + 47, block, 0);
		this.setBlock(world, i + 6, j + 0, k + 48, block, 0);
		this.setBlock(world, i + 6, j + 0, k + 49, block, 0);
		this.setBlock(world, i + 6, j + 0, k + 50, block, 0);
		this.setBlock(world, i + 6, j + 0, k + 51, block, 0);
		this.setBlock(world, i + 6, j + 0, k + 52, block, 0);
		this.setBlock(world, i + 6, j + 0, k + 53, block, 0);
		this.setBlock(world, i + 6, j + 0, k + 54, block, 0);
		this.setBlock(world, i + 6, j + 0, k + 55, block, 0);
		this.setBlock(world, i + 6, j + 0, k + 56, block, 0);
		this.setBlock(world, i + 6, j + 0, k + 57, block, 0);
		this.setBlock(world, i + 6, j + 0, k + 58, block, 0);
		this.setBlock(world, i + 6, j + 1, k + 16, block, 0);
		this.setBlock(world, i + 6, j + 1, k + 17, Blocks.air, 0);
		this.setBlock(world, i + 6, j + 1, k + 18, Blocks.air, 0);
		this.setBlock(world, i + 6, j + 1, k + 19, block, 0);
		this.setBlock(world, i + 6, j + 1, k + 20, block, 0);
		this.setBlock(world, i + 6, j + 1, k + 21, block, 0);
		this.setBlock(world, i + 6, j + 1, k + 22, block, 0);
		this.setBlock(world, i + 6, j + 1, k + 23, block, 0);
		this.setBlock(world, i + 6, j + 1, k + 24, block, 0);
		this.setBlock(world, i + 6, j + 1, k + 25, block, 0);
		this.setBlock(world, i + 6, j + 1, k + 26, block, 0);
		this.setBlock(world, i + 6, j + 1, k + 43, block, 0);
		this.setBlock(world, i + 6, j + 1, k + 44, Blocks.air, 0);
		this.setBlock(world, i + 6, j + 1, k + 45, Blocks.air, 0);
		this.setBlock(world, i + 6, j + 1, k + 46, Blocks.air, 0);
		this.setBlock(world, i + 6, j + 1, k + 47, Blocks.air, 0);
		this.setBlock(world, i + 6, j + 1, k + 48, Blocks.air, 0);
		this.setBlock(world, i + 6, j + 1, k + 49, Blocks.air, 0);
		this.setBlock(world, i + 6, j + 1, k + 50, Blocks.air, 0);
		this.setBlock(world, i + 6, j + 1, k + 51, block, 0);
		this.setBlock(world, i + 6, j + 1, k + 52, Blocks.air, 0);
		this.setBlock(world, i + 6, j + 1, k + 53, Blocks.air, 0);
		this.setBlock(world, i + 6, j + 1, k + 54, block, 0);
		this.setBlock(world, i + 6, j + 1, k + 55, block, 0);
		this.setBlock(world, i + 6, j + 1, k + 56, block, 0);
		this.setBlock(world, i + 6, j + 1, k + 57, block, 0);
		this.setBlock(world, i + 6, j + 1, k + 58, block, 0);
		this.setBlock(world, i + 6, j + 1, k + 59, block, 0);
		this.setBlock(world, i + 6, j + 2, k + 16, block, 0);
		this.setBlock(world, i + 6, j + 2, k + 19, block, 0);
		this.setBlock(world, i + 6, j + 2, k + 20, block, 0);
		this.setBlock(world, i + 6, j + 2, k + 21, block, 0);
		this.setBlock(world, i + 6, j + 2, k + 22, block, 0);
		this.setBlock(world, i + 6, j + 2, k + 23, block, 0);
		this.setBlock(world, i + 6, j + 2, k + 24, block, 0);
		this.setBlock(world, i + 6, j + 2, k + 25, block, 0);
		this.setBlock(world, i + 6, j + 2, k + 26, block, 0);
		this.setBlock(world, i + 6, j + 2, k + 43, block, 0);
		this.setBlock(world, i + 6, j + 2, k + 51, block, 0);
		this.setBlock(world, i + 6, j + 2, k + 54, stairBlock, 0);
		this.setBlock(world, i + 6, j + 2, k + 55, stairBlock, 0);
		this.setBlock(world, i + 6, j + 2, k + 56, block, 0);
		this.setBlock(world, i + 6, j + 2, k + 57, block, 0);
		this.setBlock(world, i + 6, j + 2, k + 58, block, 0);
		this.setBlock(world, i + 6, j + 2, k + 59, block, 0);
		this.setBlock(world, i + 6, j + 3, k + 16, block, 0);
		this.setBlock(world, i + 6, j + 3, k + 19, block, 0);
		this.setBlock(world, i + 6, j + 3, k + 20, block, 0);
		this.setBlock(world, i + 6, j + 3, k + 21, block, 0);
		this.setBlock(world, i + 6, j + 3, k + 22, block, 0);
		this.setBlock(world, i + 6, j + 3, k + 23, block, 0);
		this.setBlock(world, i + 6, j + 3, k + 24, block, 0);
		this.setBlock(world, i + 6, j + 3, k + 25, block, 0);
		this.setBlock(world, i + 6, j + 3, k + 26, block, 0);
		this.setBlock(world, i + 6, j + 3, k + 43, block, 0);
		this.setBlock(world, i + 6, j + 3, k + 51, block, 0);
		this.setBlock(world, i + 6, j + 3, k + 56, block, 0);
		this.setBlock(world, i + 6, j + 3, k + 57, block, 0);
		this.setBlock(world, i + 6, j + 3, k + 58, block, 0);
		this.setBlock(world, i + 6, j + 3, k + 59, block, 0);
		this.setBlock(world, i + 6, j + 4, k + 16, block, 0);
		this.setBlock(world, i + 6, j + 4, k + 19, block, 0);
		this.setBlock(world, i + 6, j + 4, k + 20, block, 0);
		this.setBlock(world, i + 6, j + 4, k + 21, block, 0);
		this.setBlock(world, i + 6, j + 4, k + 22, block, 0);
		this.setBlock(world, i + 6, j + 4, k + 23, block, 0);
		this.setBlock(world, i + 6, j + 4, k + 24, block, 0);
		this.setBlock(world, i + 6, j + 4, k + 25, block, 0);
		this.setBlock(world, i + 6, j + 4, k + 26, block, 0);
		this.setBlock(world, i + 6, j + 4, k + 43, block, 0);
		this.setBlock(world, i + 6, j + 4, k + 51, block, 0);
		this.setBlock(world, i + 6, j + 4, k + 56, block, 0);
		this.setBlock(world, i + 6, j + 4, k + 57, block, 0);
		this.setBlock(world, i + 6, j + 4, k + 58, block, 0);
		this.setBlock(world, i + 6, j + 4, k + 59, block, 0);
		this.setBlock(world, i + 6, j + 5, k + 16, block, 0);
		this.setBlock(world, i + 6, j + 5, k + 17, block, 0);
		this.setBlock(world, i + 6, j + 5, k + 18, block, 0);
		this.setBlock(world, i + 6, j + 5, k + 19, block, 0);
		this.setBlock(world, i + 6, j + 5, k + 20, block, 0);
		this.setBlock(world, i + 6, j + 5, k + 21, block, 0);
		this.setBlock(world, i + 6, j + 5, k + 22, block, 0);
		this.setBlock(world, i + 6, j + 5, k + 23, block, 0);
		this.setBlock(world, i + 6, j + 5, k + 24, block, 0);
		this.setBlock(world, i + 6, j + 5, k + 25, block, 0);
		this.setBlock(world, i + 6, j + 5, k + 26, block, 0);
		this.setBlock(world, i + 6, j + 5, k + 43, block, 0);
		this.setBlock(world, i + 6, j + 5, k + 44, block, 0);
		this.setBlock(world, i + 6, j + 5, k + 45, block, 0);
		this.setBlock(world, i + 6, j + 5, k + 46, block, 0);
		this.setBlock(world, i + 6, j + 5, k + 47, block, 0);
		this.setBlock(world, i + 6, j + 5, k + 48, block, 0);
		this.setBlock(world, i + 6, j + 5, k + 49, block, 0);
		this.setBlock(world, i + 6, j + 5, k + 50, block, 0);
		this.setBlock(world, i + 6, j + 5, k + 51, block, 0);
		this.setBlock(world, i + 6, j + 5, k + 52, block, 0);
		this.setBlock(world, i + 6, j + 5, k + 53, block, 0);
		this.setBlock(world, i + 6, j + 5, k + 56, block, 0);
		this.setBlock(world, i + 6, j + 5, k + 57, block, 0);
		this.setBlock(world, i + 6, j + 5, k + 58, block, 0);
		this.setBlock(world, i + 6, j + 5, k + 59, block, 0);
		this.setBlock(world, i + 6, j + 6, k + 16, block, 0);
		this.setBlock(world, i + 6, j + 6, k + 17, block, 0);
		this.setBlock(world, i + 6, j + 6, k + 18, block, 0);
		this.setBlock(world, i + 6, j + 6, k + 19, block, 0);
		this.setBlock(world, i + 6, j + 6, k + 20, block, 0);
		this.setBlock(world, i + 6, j + 6, k + 21, block, 0);
		this.setBlock(world, i + 6, j + 6, k + 22, block, 0);
		this.setBlock(world, i + 6, j + 6, k + 23, block, 0);
		this.setBlock(world, i + 6, j + 6, k + 24, block, 0);
		this.setBlock(world, i + 6, j + 6, k + 25, block, 0);
		this.setBlock(world, i + 6, j + 6, k + 26, block, 0);
		this.setBlock(world, i + 6, j + 6, k + 43, block, 0);
		this.setBlock(world, i + 6, j + 6, k + 44, block, 0);
		this.setBlock(world, i + 6, j + 6, k + 45, block, 0);
		this.setBlock(world, i + 6, j + 6, k + 46, block, 0);
		this.setBlock(world, i + 6, j + 6, k + 47, block, 0);
		this.setBlock(world, i + 6, j + 6, k + 48, block, 0);
		this.setBlock(world, i + 6, j + 6, k + 49, block, 0);
		this.setBlock(world, i + 6, j + 6, k + 50, block, 0);
		this.setBlock(world, i + 6, j + 6, k + 51, block, 0);
		this.setBlock(world, i + 6, j + 6, k + 52, block, 0);
		this.setBlock(world, i + 6, j + 6, k + 53, block, 0);
		this.setBlock(world, i + 6, j + 6, k + 56, block, 0);
		this.setBlock(world, i + 6, j + 6, k + 57, block, 0);
		this.setBlock(world, i + 6, j + 6, k + 58, block, 0);
		this.setBlock(world, i + 6, j + 6, k + 59, block, 0);
		this.setBlock(world, i + 6, j + 7, k + 16, block, 0);
		this.setBlock(world, i + 6, j + 7, k + 17, block, 0);
		this.setBlock(world, i + 6, j + 7, k + 18, block, 0);
		this.setBlock(world, i + 6, j + 7, k + 19, block, 0);
		this.setBlock(world, i + 6, j + 7, k + 20, block, 0);
		this.setBlock(world, i + 6, j + 7, k + 21, block, 0);
		this.setBlock(world, i + 6, j + 7, k + 22, block, 0);
		this.setBlock(world, i + 6, j + 7, k + 23, block, 0);
		this.setBlock(world, i + 6, j + 7, k + 24, block, 0);
		this.setBlock(world, i + 6, j + 7, k + 25, block, 0);
		this.setBlock(world, i + 6, j + 7, k + 26, block, 0);
		this.setBlock(world, i + 6, j + 7, k + 43, block, 0);
		this.setBlock(world, i + 6, j + 7, k + 44, block, 0);
		this.setBlock(world, i + 6, j + 7, k + 45, block, 0);
		this.setBlock(world, i + 6, j + 7, k + 46, block, 0);
		this.setBlock(world, i + 6, j + 7, k + 47, block, 0);
		this.setBlock(world, i + 6, j + 7, k + 48, block, 0);
		this.setBlock(world, i + 6, j + 7, k + 49, block, 0);
		this.setBlock(world, i + 6, j + 7, k + 50, block, 0);
		this.setBlock(world, i + 6, j + 7, k + 51, block, 0);
		this.setBlock(world, i + 6, j + 7, k + 52, block, 0);
		this.setBlock(world, i + 6, j + 7, k + 53, block, 0);
		this.setBlock(world, i + 6, j + 7, k + 54, stairBlock, 5);
		this.setBlock(world, i + 6, j + 7, k + 55, stairBlock, 5);
		this.setBlock(world, i + 6, j + 7, k + 56, block, 0);
		this.setBlock(world, i + 6, j + 7, k + 57, block, 0);
		this.setBlock(world, i + 6, j + 7, k + 58, block, 0);
		this.setBlock(world, i + 6, j + 7, k + 59, block, 0);
		this.setBlock(world, i + 6, j + 8, k + 16, block, 0);
		this.setBlock(world, i + 6, j + 8, k + 17, block, 0);
		this.setBlock(world, i + 6, j + 8, k + 18, block, 0);
		this.setBlock(world, i + 6, j + 8, k + 19, block, 0);
		this.setBlock(world, i + 6, j + 8, k + 20, block, 0);
		this.setBlock(world, i + 6, j + 8, k + 21, block, 0);
		this.setBlock(world, i + 6, j + 8, k + 22, block, 0);
		this.setBlock(world, i + 6, j + 8, k + 23, block, 0);
		this.setBlock(world, i + 6, j + 8, k + 24, block, 0);
		this.setBlock(world, i + 6, j + 8, k + 25, block, 0);
		this.setBlock(world, i + 6, j + 8, k + 26, block, 0);
		this.setBlock(world, i + 6, j + 8, k + 43, block, 0);
		this.setBlock(world, i + 6, j + 8, k + 44, block, 0);
		this.setBlock(world, i + 6, j + 8, k + 45, block, 0);
		this.setBlock(world, i + 6, j + 8, k + 46, block, 0);
		this.setBlock(world, i + 6, j + 8, k + 47, block, 0);
		this.setBlock(world, i + 6, j + 8, k + 48, block, 0);
		this.setBlock(world, i + 6, j + 8, k + 49, block, 0);
		this.setBlock(world, i + 6, j + 8, k + 50, block, 0);
		this.setBlock(world, i + 6, j + 8, k + 51, block, 0);
		this.setBlock(world, i + 6, j + 8, k + 52, block, 0);
		this.setBlock(world, i + 6, j + 8, k + 53, block, 0);
		this.setBlock(world, i + 6, j + 8, k + 54, block, 0);
		this.setBlock(world, i + 6, j + 8, k + 55, block, 0);
		this.setBlock(world, i + 6, j + 8, k + 56, block, 0);
		this.setBlock(world, i + 6, j + 8, k + 57, block, 0);
		this.setBlock(world, i + 6, j + 8, k + 58, block, 0);
		this.setBlock(world, i + 6, j + 8, k + 59, block, 0);
		this.setBlock(world, i + 6, j + 9, k + 16, block, 0);
		this.setBlock(world, i + 6, j + 9, k + 17, block, 0);
		this.setBlock(world, i + 6, j + 9, k + 18, block, 0);

		generate2(world, rand, i, j, k);
		return true;
	}

	public boolean generate2(World world, Random rand, int i, int j, int k) {
		this.setBlock(world, i + 6, j + 9, k + 19, block, 0);
		this.setBlock(world, i + 6, j + 9, k + 20, block, 0);
		this.setBlock(world, i + 6, j + 9, k + 21, block, 0);
		this.setBlock(world, i + 6, j + 9, k + 22, block, 0);
		this.setBlock(world, i + 6, j + 9, k + 23, block, 0);
		this.setBlock(world, i + 6, j + 9, k + 24, block, 0);
		this.setBlock(world, i + 6, j + 9, k + 25, block, 0);
		this.setBlock(world, i + 6, j + 9, k + 26, block, 0);
		this.setBlock(world, i + 6, j + 9, k + 43, block, 0);
		this.setBlock(world, i + 6, j + 9, k + 44, block, 0);
		this.setBlock(world, i + 6, j + 9, k + 45, block, 0);
		this.setBlock(world, i + 6, j + 9, k + 46, block, 0);
		this.setBlock(world, i + 6, j + 9, k + 47, block, 0);
		this.setBlock(world, i + 6, j + 9, k + 48, block, 0);
		this.setBlock(world, i + 6, j + 9, k + 49, block, 0);
		this.setBlock(world, i + 6, j + 9, k + 50, block, 0);
		this.setBlock(world, i + 6, j + 9, k + 51, block, 0);
		this.setBlock(world, i + 6, j + 9, k + 52, block, 0);
		this.setBlock(world, i + 6, j + 9, k + 53, block, 0);
		this.setBlock(world, i + 6, j + 9, k + 54, block, 0);
		this.setBlock(world, i + 6, j + 9, k + 55, block, 0);
		this.setBlock(world, i + 6, j + 9, k + 56, block, 0);
		this.setBlock(world, i + 6, j + 9, k + 57, block, 0);
		this.setBlock(world, i + 6, j + 9, k + 58, block, 0);
		this.setBlock(world, i + 6, j + 9, k + 59, block, 0);
		this.setBlock(world, i + 6, j + 10, k + 17, block, 0);
		this.setBlock(world, i + 6, j + 10, k + 18, block, 0);
		this.setBlock(world, i + 6, j + 10, k + 19, block, 0);
		this.setBlock(world, i + 6, j + 10, k + 20, block, 0);
		this.setBlock(world, i + 6, j + 10, k + 21, block, 0);
		this.setBlock(world, i + 6, j + 10, k + 22, block, 0);
		this.setBlock(world, i + 6, j + 10, k + 23, block, 0);
		this.setBlock(world, i + 6, j + 10, k + 24, block, 0);
		this.setBlock(world, i + 6, j + 10, k + 25, block, 0);
		this.setBlock(world, i + 6, j + 10, k + 44, block, 0);
		this.setBlock(world, i + 6, j + 10, k + 45, block, 0);
		this.setBlock(world, i + 6, j + 10, k + 46, block, 0);
		this.setBlock(world, i + 6, j + 10, k + 47, block, 0);
		this.setBlock(world, i + 6, j + 10, k + 48, block, 0);
		this.setBlock(world, i + 6, j + 10, k + 49, block, 0);
		this.setBlock(world, i + 6, j + 10, k + 50, block, 0);
		this.setBlock(world, i + 6, j + 10, k + 51, block, 0);
		this.setBlock(world, i + 6, j + 10, k + 52, block, 0);
		this.setBlock(world, i + 6, j + 10, k + 53, block, 0);
		this.setBlock(world, i + 6, j + 10, k + 54, block, 0);
		this.setBlock(world, i + 6, j + 10, k + 55, block, 0);
		this.setBlock(world, i + 6, j + 10, k + 56, block, 0);
		this.setBlock(world, i + 6, j + 10, k + 57, block, 0);
		this.setBlock(world, i + 6, j + 10, k + 58, block, 0);
		this.setBlock(world, i + 7, j + 0, k + 17, block, 0);
		this.setBlock(world, i + 7, j + 0, k + 18, block, 0);
		this.setBlock(world, i + 7, j + 0, k + 19, block, 0);
		this.setBlock(world, i + 7, j + 0, k + 20, block, 0);
		this.setBlock(world, i + 7, j + 0, k + 21, block, 0);
		this.setBlock(world, i + 7, j + 0, k + 22, block, 0);
		this.setBlock(world, i + 7, j + 0, k + 23, block, 0);
		this.setBlock(world, i + 7, j + 0, k + 24, block, 0);
		this.setBlock(world, i + 7, j + 0, k + 25, block, 0);
		this.setBlock(world, i + 7, j + 0, k + 44, block, 0);
		this.setBlock(world, i + 7, j + 0, k + 45, block, 0);
		this.setBlock(world, i + 7, j + 0, k + 46, block, 0);
		this.setBlock(world, i + 7, j + 0, k + 47, block, 0);
		this.setBlock(world, i + 7, j + 0, k + 48, block, 0);
		this.setBlock(world, i + 7, j + 0, k + 49, block, 0);
		this.setBlock(world, i + 7, j + 0, k + 50, block, 0);
		this.setBlock(world, i + 7, j + 0, k + 51, block, 0);
		this.setBlock(world, i + 7, j + 0, k + 52, block, 0);
		this.setBlock(world, i + 7, j + 0, k + 53, block, 0);
		this.setBlock(world, i + 7, j + 0, k + 54, block, 0);
		this.setBlock(world, i + 7, j + 0, k + 55, block, 0);
		this.setBlock(world, i + 7, j + 0, k + 56, block, 0);
		this.setBlock(world, i + 7, j + 0, k + 57, block, 0);
		this.setBlock(world, i + 7, j + 0, k + 58, block, 0);
		this.setBlock(world, i + 7, j + 1, k + 16, block, 0);
		this.setBlock(world, i + 7, j + 1, k + 17, Blocks.air, 0);
		this.setBlock(world, i + 7, j + 1, k + 18, Blocks.air, 0);
		this.setBlock(world, i + 7, j + 1, k + 19, Blocks.air, 0);
		this.setBlock(world, i + 7, j + 1, k + 20, block, 0);
		this.setBlock(world, i + 7, j + 1, k + 21, block, 0);
		this.setBlock(world, i + 7, j + 1, k + 22, block, 0);
		this.setBlock(world, i + 7, j + 1, k + 23, Blocks.air, 0);
		this.setBlock(world, i + 7, j + 1, k + 24, Blocks.air, 0);
		this.setBlock(world, i + 7, j + 1, k + 25, Blocks.air, 0);
		this.setBlock(world, i + 7, j + 1, k + 26, block, 0);
		this.setBlock(world, i + 7, j + 1, k + 43, block, 0);
		this.setBlock(world, i + 7, j + 1, k + 44, Blocks.air, 0);
		this.setBlock(world, i + 7, j + 1, k + 45, Blocks.air, 0);
		this.setBlock(world, i + 7, j + 1, k + 46, block, 0);
		this.setBlock(world, i + 7, j + 1, k + 47, block, 0);
		this.setBlock(world, i + 7, j + 1, k + 48, block, 0);
		this.setBlock(world, i + 7, j + 1, k + 49, Blocks.air, 0);
		this.setBlock(world, i + 7, j + 1, k + 50, Blocks.air, 0);
		this.setBlock(world, i + 7, j + 1, k + 51, block, 0);
		this.setBlock(world, i + 7, j + 1, k + 52, Blocks.air, 0);
		this.setBlock(world, i + 7, j + 1, k + 53, Blocks.air, 0);
		this.setBlock(world, i + 7, j + 1, k + 54, block, 0);
		this.setBlock(world, i + 7, j + 1, k + 55, block, 0);
		this.setBlock(world, i + 7, j + 1, k + 56, block, 0);
		this.setBlock(world, i + 7, j + 1, k + 57, block, 0);
		this.setBlock(world, i + 7, j + 1, k + 58, block, 0);
		this.setBlock(world, i + 7, j + 1, k + 59, block, 0);
		this.setBlock(world, i + 7, j + 2, k + 16, block, 0);
		this.setBlock(world, i + 7, j + 2, k + 20, block, 0);
		this.setBlock(world, i + 7, j + 2, k + 21, block, 0);
		this.setBlock(world, i + 7, j + 2, k + 22, block, 0);
		this.setBlock(world, i + 7, j + 2, k + 26, block, 0);
		this.setBlock(world, i + 7, j + 2, k + 43, block, 0);
		this.setBlock(world, i + 7, j + 2, k + 46, block, 0);
		this.setBlock(world, i + 7, j + 2, k + 47, block, 0);
		this.setBlock(world, i + 7, j + 2, k + 48, block, 0);
		this.setBlock(world, i + 7, j + 2, k + 51, block, 0);
		this.setBlock(world, i + 7, j + 2, k + 54, block, 0);
		this.setBlock(world, i + 7, j + 2, k + 55, block, 0);
		this.setBlock(world, i + 7, j + 2, k + 56, block, 0);
		this.setBlock(world, i + 7, j + 2, k + 57, block, 0);
		this.setBlock(world, i + 7, j + 2, k + 58, block, 0);
		this.setBlock(world, i + 7, j + 2, k + 59, block, 0);
		this.setBlock(world, i + 7, j + 3, k + 16, block, 0);
		this.setBlock(world, i + 7, j + 3, k + 20, block, 0);
		this.setBlock(world, i + 7, j + 3, k + 21, block, 0);
		this.setBlock(world, i + 7, j + 3, k + 22, block, 0);
		this.setBlock(world, i + 7, j + 3, k + 26, block, 0);
		this.setBlock(world, i + 7, j + 3, k + 43, block, 0);
		this.setBlock(world, i + 7, j + 3, k + 46, block, 0);
		this.setBlock(world, i + 7, j + 3, k + 47, block, 0);
		this.setBlock(world, i + 7, j + 3, k + 48, block, 0);
		this.setBlock(world, i + 7, j + 3, k + 51, block, 0);
		this.setBlock(world, i + 7, j + 3, k + 54, stairBlock, 0);
		this.setBlock(world, i + 7, j + 3, k + 55, stairBlock, 0);
		this.setBlock(world, i + 7, j + 3, k + 56, block, 0);
		this.setBlock(world, i + 7, j + 3, k + 57, block, 0);
		this.setBlock(world, i + 7, j + 3, k + 58, block, 0);
		this.setBlock(world, i + 7, j + 3, k + 59, block, 0);
		this.setBlock(world, i + 7, j + 4, k + 16, block, 0);
		this.setBlock(world, i + 7, j + 4, k + 20, block, 0);
		this.setBlock(world, i + 7, j + 4, k + 21, block, 0);
		this.setBlock(world, i + 7, j + 4, k + 22, block, 0);
		this.setBlock(world, i + 7, j + 4, k + 26, block, 0);
		this.setBlock(world, i + 7, j + 4, k + 43, block, 0);
		this.setBlock(world, i + 7, j + 4, k + 44, stairBlock, 7);
		this.setBlock(world, i + 7, j + 4, k + 45, stairBlock, 6);
		this.setBlock(world, i + 7, j + 4, k + 46, block, 0);
		this.setBlock(world, i + 7, j + 4, k + 47, block, 0);
		this.setBlock(world, i + 7, j + 4, k + 48, block, 0);
		this.setBlock(world, i + 7, j + 4, k + 51, block, 0);
		this.setBlock(world, i + 7, j + 4, k + 56, block, 0);
		this.setBlock(world, i + 7, j + 4, k + 57, block, 0);
		this.setBlock(world, i + 7, j + 4, k + 58, block, 0);
		this.setBlock(world, i + 7, j + 4, k + 59, block, 0);
		this.setBlock(world, i + 7, j + 5, k + 16, block, 0);
		this.setBlock(world, i + 7, j + 5, k + 17, block, 0);
		this.setBlock(world, i + 7, j + 5, k + 18, block, 0);
		this.setBlock(world, i + 7, j + 5, k + 19, block, 0);
		this.setBlock(world, i + 7, j + 5, k + 20, block, 0);
		this.setBlock(world, i + 7, j + 5, k + 21, block, 0);
		this.setBlock(world, i + 7, j + 5, k + 22, block, 0);
		this.setBlock(world, i + 7, j + 5, k + 23, block, 0);
		this.setBlock(world, i + 7, j + 5, k + 24, block, 0);
		this.setBlock(world, i + 7, j + 5, k + 25, block, 0);
		this.setBlock(world, i + 7, j + 5, k + 26, block, 0);
		this.setBlock(world, i + 7, j + 5, k + 43, block, 0);
		this.setBlock(world, i + 7, j + 5, k + 44, block, 0);
		this.setBlock(world, i + 7, j + 5, k + 45, block, 0);
		this.setBlock(world, i + 7, j + 5, k + 46, block, 0);
		this.setBlock(world, i + 7, j + 5, k + 47, block, 0);
		this.setBlock(world, i + 7, j + 5, k + 48, block, 0);
		this.setBlock(world, i + 7, j + 5, k + 49, block, 0);
		this.setBlock(world, i + 7, j + 5, k + 50, block, 0);
		this.setBlock(world, i + 7, j + 5, k + 51, block, 0);
		this.setBlock(world, i + 7, j + 5, k + 52, block, 0);
		this.setBlock(world, i + 7, j + 5, k + 53, block, 0);
		this.setBlock(world, i + 7, j + 5, k + 56, block, 0);
		this.setBlock(world, i + 7, j + 5, k + 57, block, 0);
		this.setBlock(world, i + 7, j + 5, k + 58, block, 0);
		this.setBlock(world, i + 7, j + 5, k + 59, block, 0);
		this.setBlock(world, i + 7, j + 6, k + 16, block, 0);
		this.setBlock(world, i + 7, j + 6, k + 17, block, 0);
		this.setBlock(world, i + 7, j + 6, k + 18, block, 0);
		this.setBlock(world, i + 7, j + 6, k + 19, block, 0);
		this.setBlock(world, i + 7, j + 6, k + 20, block, 0);
		this.setBlock(world, i + 7, j + 6, k + 21, block, 0);
		this.setBlock(world, i + 7, j + 6, k + 22, block, 0);
		this.setBlock(world, i + 7, j + 6, k + 23, block, 0);
		this.setBlock(world, i + 7, j + 6, k + 24, block, 0);
		this.setBlock(world, i + 7, j + 6, k + 25, block, 0);
		this.setBlock(world, i + 7, j + 6, k + 26, block, 0);
		this.setBlock(world, i + 7, j + 6, k + 43, block, 0);
		this.setBlock(world, i + 7, j + 6, k + 44, block, 0);
		this.setBlock(world, i + 7, j + 6, k + 45, block, 0);
		this.setBlock(world, i + 7, j + 6, k + 46, block, 0);
		this.setBlock(world, i + 7, j + 6, k + 47, block, 0);
		this.setBlock(world, i + 7, j + 6, k + 48, block, 0);
		this.setBlock(world, i + 7, j + 6, k + 49, block, 0);
		this.setBlock(world, i + 7, j + 6, k + 50, block, 0);
		this.setBlock(world, i + 7, j + 6, k + 51, block, 0);
		this.setBlock(world, i + 7, j + 6, k + 52, block, 0);
		this.setBlock(world, i + 7, j + 6, k + 53, block, 0);
		this.setBlock(world, i + 7, j + 6, k + 56, block, 0);
		this.setBlock(world, i + 7, j + 6, k + 57, block, 0);
		this.setBlock(world, i + 7, j + 6, k + 58, block, 0);
		this.setBlock(world, i + 7, j + 6, k + 59, block, 0);
		this.setBlock(world, i + 7, j + 7, k + 16, block, 0);
		this.setBlock(world, i + 7, j + 7, k + 17, block, 0);
		this.setBlock(world, i + 7, j + 7, k + 18, block, 0);
		this.setBlock(world, i + 7, j + 7, k + 19, block, 0);
		this.setBlock(world, i + 7, j + 7, k + 20, block, 0);
		this.setBlock(world, i + 7, j + 7, k + 21, block, 0);
		this.setBlock(world, i + 7, j + 7, k + 22, block, 0);
		this.setBlock(world, i + 7, j + 7, k + 23, block, 0);
		this.setBlock(world, i + 7, j + 7, k + 24, block, 0);
		this.setBlock(world, i + 7, j + 7, k + 25, block, 0);
		this.setBlock(world, i + 7, j + 7, k + 26, block, 0);
		this.setBlock(world, i + 7, j + 7, k + 43, block, 0);
		this.setBlock(world, i + 7, j + 7, k + 44, block, 0);
		this.setBlock(world, i + 7, j + 7, k + 45, block, 0);
		this.setBlock(world, i + 7, j + 7, k + 46, block, 0);
		this.setBlock(world, i + 7, j + 7, k + 47, block, 0);
		this.setBlock(world, i + 7, j + 7, k + 48, block, 0);
		this.setBlock(world, i + 7, j + 7, k + 49, block, 0);
		this.setBlock(world, i + 7, j + 7, k + 50, block, 0);
		this.setBlock(world, i + 7, j + 7, k + 51, block, 0);
		this.setBlock(world, i + 7, j + 7, k + 52, block, 0);
		this.setBlock(world, i + 7, j + 7, k + 53, block, 0);
		this.setBlock(world, i + 7, j + 7, k + 56, block, 0);
		this.setBlock(world, i + 7, j + 7, k + 57, block, 0);
		this.setBlock(world, i + 7, j + 7, k + 58, block, 0);
		this.setBlock(world, i + 7, j + 7, k + 59, block, 0);
		this.setBlock(world, i + 7, j + 8, k + 16, block, 0);
		this.setBlock(world, i + 7, j + 8, k + 17, block, 0);
		this.setBlock(world, i + 7, j + 8, k + 18, block, 0);
		this.setBlock(world, i + 7, j + 8, k + 19, block, 0);
		this.setBlock(world, i + 7, j + 8, k + 20, block, 0);
		this.setBlock(world, i + 7, j + 8, k + 21, block, 0);
		this.setBlock(world, i + 7, j + 8, k + 22, block, 0);
		this.setBlock(world, i + 7, j + 8, k + 23, block, 0);
		this.setBlock(world, i + 7, j + 8, k + 24, block, 0);
		this.setBlock(world, i + 7, j + 8, k + 25, block, 0);
		this.setBlock(world, i + 7, j + 8, k + 26, block, 0);
		this.setBlock(world, i + 7, j + 8, k + 43, block, 0);
		this.setBlock(world, i + 7, j + 8, k + 44, block, 0);
		this.setBlock(world, i + 7, j + 8, k + 45, block, 0);
		this.setBlock(world, i + 7, j + 8, k + 46, block, 0);
		this.setBlock(world, i + 7, j + 8, k + 47, block, 0);
		this.setBlock(world, i + 7, j + 8, k + 48, block, 0);
		this.setBlock(world, i + 7, j + 8, k + 49, block, 0);
		this.setBlock(world, i + 7, j + 8, k + 50, block, 0);
		this.setBlock(world, i + 7, j + 8, k + 51, block, 0);
		this.setBlock(world, i + 7, j + 8, k + 52, block, 0);
		this.setBlock(world, i + 7, j + 8, k + 53, block, 0);
		this.setBlock(world, i + 7, j + 8, k + 54, stairBlock, 5);
		this.setBlock(world, i + 7, j + 8, k + 55, stairBlock, 5);
